Workbook

Sheet Baza
B1: OPERATOR:2 | C1: OPERATOR:2 | D1: OPERATOR:4 | E1: OPERATOR:8 | F1: OPERATOR:9 | G1: OPERATOR:5 | H1: OPERATOR:10 | I1: OPERATOR:11 | J1: 5 | K1: 5 | L1: 6 | M1: 6 | N1: 13 | O1: 13 | P1: 14 | Q1: 14 | R1: 40 | S1: 40 | T1: 40 | U1: 40 | V1: 40 | W1: 40 | X1: 40 | Y1: 40 | Z1: 40 | AA1: 40 | AB1: 40 | AC1: 40 | AD1: 40 | AE1: 40 | AF1: 40 | AG1: 40 | AH1: 40 | AI1: 40 | AJ1: 40 | AK1: 40 | AL1: 40 | AM1: 40 | AN1: 40 | AO1: 40 | AP1: 40 | AQ1: 40 | AR1: 40 | AS1: 40 | AT1: 40 | AU1: 40 | AV1: 40 | AW1: 40 | AX1: 40 | AY1: 40 | AZ1: 40 | BA1: 40 | BB1: 40 | BC1: 40 | BD1: 40 | BE1: 40 | BF1: 40 | BG1: 40 | BH1: 40 | BI1: 40 | BJ1: 40 | BK1: 40 | BL1: 40 | BM1: 40 | BN1: 40 | BO1: 40 | BP1: 40 | BQ1: 40 | BR1: 40 | BS1: 40 | BT1: 40 | BU1: 40 | BV1: 41 | BW1: 41 | BX1: 41 | BY1: 41 | BZ1: 41 | CA1: 41 | CB1: 41 | CC1: 41 | CD1: 41 | CE1: 41 | CF1: 41 | CG1: 41 | CH1: 41 | CI1: 41 | CJ1: 41 | CK1: 41 | CL1: 41 | CM1: 41 | CN1: 41 | CO1: 41 | CP1: 41 | CQ1: 41 | CR1: 41 | CS1: 41 | CT1: 41 | CU1: 41 | CV1: 41 | CW1: 41 | CX1: 41 | CY1: 41 | CZ1: 41 | DA1: 41 | DB1: 41 | DC1: 41 | DD1: 41 | DE1: 41 | DF1: 41 | DG1: 41 | DH1: 41 | DI1: 41 | DJ1: 41 | DK1: 41 | DL1: 41 | DM1: 41 | DN1: 41 | DO1: 41 | DP1: 41 | DQ1: 41 | DR1: 41 | DS1: 41 | DT1: 41 | DU1: 41 | DV1: 41 | DW1: 41 | DX1: 41 | DY1: 41 | DZ1: 50 | EA1: 50 | EB1: 50 | EC1: 50 | ED1: 50 | EE1: 50 | EF1: 50 | EG1: 50 | EH1: 50 | EI1: 50 | EJ1: 50 | EK1: 50 | EL1: 50 | EM1: 50 | EN1: 50 | EO1: 50 | EP1: 50 | EQ1: 50 | ER1: 50 | ES1: 50 | ET1: 50 | EU1: 50 | EV1: 50 | EW1: 50 | EX1: 50 | EY1: 50 | EZ1: 50 | FA1: 50 | FB1: 50 | FC1: 50 | FD1: 50 | FE1: 50 | FF1: 50 | FG1: 50 | FH1: 50 | FI1: 50 | FJ1: 50 | FK1: 50 | FL1: 50 | FM1: 50 | FN1: 50 | FO1: 50 | FP1: 50 | FQ1: 50 | FR1: 50 | FS1: 50 | FT1: 50 | FU1: 50 | FV1: 50 | FW1: 50 | FX1: 50 | FY1: 50 | FZ1: 50 | GA1: 50 | GB1: 50 | GC1: 50 | GD1: 50 | GE1: 50 | GF1: 50 | GG1: 50 | GH1: 50 | GI1: 50 | GJ1: 50 | GK1: 50 | GL1: 50 | GM1: 50 | GN1: 50 | GO1: 50 | GP1: 50 | GQ1: 50 | GR1: 50 | GS1: 50 | GT1: 50 | GU1: 50 | GV1: 50 | GW1: 50 | GX1: 51 | GY1: 51 | GZ1: 51 | HA1: 51 | HB1: 51 | HC1: 51 | HD1: 51 | HE1: 51 | HF1: 51 | HG1: 51 | HH1: 51 | HI1: 51 | HJ1: 51 | HK1: 51 | HL1: 51 | HM1: 51 | HN1: 51 | HO1: 51 | HP1: 51 | HQ1: 51 | HR1: 51 | HS1: 51 | HT1: 51 | HU1: 51 | HV1: 51 | HW1: 51 | HX1: 51 | HY1: 51 | HZ1: 51 | IA1: 51 | IB1: 51 | IC1: 51 | ID1: 51 | IE1: 51 | IF1: 51 | IG1: 51 | IH1: 51 | II1: 51 | IJ1: 51 | IK1: 51 | IL1: 51 | IM1: 51 | IN1: 51 | IO1: 51 | IP1: 51 | IQ1: 51 | IR1: 51 | IS1: 51 | IT1: 51 | IU1: 51 | IV1: 51 | IW1: 51 | IX1: 51 | IY1: 51 | IZ1: 51 | JA1: 51 | JB1: 51 | JC1: 51 | JD1: 51 | JE1: 51 | JF1: 51 | JG1: 51 | JH1: 51 | JI1: 51 | JJ1: 51 | JK1: 51 | JL1: 51 | JM1: 51 | JN1: 51 | JO1: 51 | JP1: 51 | JQ1: 51 | JR1: 51 | JS1: 51 | JT1: 51 | JU1: 51 | JV1: 60 | JW1: 60 | JX1: 60 | JY1: 60 | JZ1: 60 | KA1: 60 | KB1: 60 | KC1: 60 | KD1: 60 | KE1: 60 | KF1: 60 | KG1: 60 | KH1: 60 | KI1: 60 | KJ1: 60 | KK1: 60 | KL1: 60 | KM1: 60 | KN1: 60 | KO1: 60 | KP1: 60 | KQ1: 60 | KR1: 60 | KS1: 60 | KT1: 60 | KU1: 60 | KV1: 60 | KW1: 60 | KX1: 60 | KY1: 60 | KZ1: 60 | LA1: 60 | LB1: 60 | LC1: 60 | LD1: 60 | LE1: 60 | LF1: 60 | LG1: 60 | LH1: 60 | LI1: 60 | LJ1: 60 | LK1: 60 | LL1: 60 | LM1: 60 | LN1: 60 | LO1: 60 | LP1: 60 | LQ1: 60 | LR1: 60 | LS1: 60 | LT1: 60 | LU1: 60 | LV1: 60 | LW1: 60 | LX1: 60 | LY1: 60 | LZ1: 60 | MA1: 60 | MB1: 60 | MC1: 60 | MD1: 61 | ME1: 61 | MF1: 61 | MG1: 61 | MH1: 61 | MI1: 61 | MJ1: 61 | MK1: 61 | ML1: 61 | MM1: 61 | MN1: 61 | MO1: 61 | MP1: 61 | MQ1: 61 | MR1: 61 | MS1: 61 | MT1: 61 | MU1: 61 | MV1: 61 | MW1: 61 | MX1: 61 | MY1: 61 | MZ1: 61 | NA1: 61 | NB1: 61 | NC1: 61 | ND1: 61 | NE1: 61 | NF1: 61 | NG1: 61 | NH1: 61 | NI1: 61 | NJ1: 61 | NK1: 61 | NL1: 61 | NM1: 61 | NN1: 61 | NO1: 61 | NP1: 61 | NQ1: 61 | NR1: 61 | NS1: 61 | NT1: 61 | NU1: 61 | NV1: 61 | NW1: 61 | NX1: 61 | NY1: 61 | NZ1: 61 | OA1: 61 | OB1: 61 | OC1: 61 | OD1: 61 | OE1: 61 | OF1: 61 | OG1: 61 | OH1: 61 | OI1: 61 | OJ1: 61 | OK1: 61 | OL1: 70 | OM1: 70 | ON1: 70 | OO1: 70 | OP1: 70 | OQ1: 70 | OR1: 70 | OS1: 70 | OT1: 70 | OU1: 70 | OV1: 70 | OW1: 70 | OX1: 70 | OY1: 70 | OZ1: 70 | PA1: 70 | PB1: 70 | PC1: 70 | PD1: 71 | PE1: 71 | PF1: 71 | PG1: 71 | PH1: 71 | PI1: 71 | PJ1: 71 | PK1: 71 | PL1: 71 | PM1: 71 | PN1: 71 | PO1: 71 | PP1: 71 | PQ1: 71 | PR1: 71 | PS1: 71 | PT1: 71 | PU1: 71 | PV1: 80 | PW1: 80 | PX1: 80 | PY1: 80 | PZ1: 80 | QA1: 81 | QB1: 81 | QC1: 81 | QD1: 81 | QE1: 81 | QF1: 90 | QG1: 90 | QH1: 90 | QI1: 90 | QJ1: 91 | QK1: 91 | QL1: 91 | QM1: 91 | QN1: 92 | QO1: 92 | QP1: 92 | QQ1: 92 | QR1: 93 | QS1: 93 | QT1: 93 | QU1: 93
B2: Kąt obrotu osi X | C2: Kąt obrotu osi Y | D2: Area_NM (Amp_full-Amp_NM) | E2: Area NM_005 (Aev_005-Amp_005) | F2: Area NM_05 (Aev_05-Amp_05) | G2: Procent_NM (((Area_NM/Aev)*100)) | H2: Procent NM_005 (((Area_NM_005/Aev)*100)) | I2: Procent NM_05 (((Area_NM_05/Aev)*100)) | J2: Amp | K2: Aev | L2: Amp | M2: Aev | N2: Amp | O2: Aev | P2: Amp | Q2: Aev | R2: Pp[Średnia] | S2: Pp[Std odch] | T2: Pp[Min] | U2: Pp[Max] | V2: Pv[Średnia] | W2: Pv[Std odch] | X2: Pv[Min] | Y2: Pv[Max] | Z2: Pz[Średnia] | AA2: Pz[Std odch] | AB2: Pz[Min] | AC2: Pz[Max] | AD2: Pc (Brak uśredniania (pojedyncza wartość))[Średnia] | AE2: Pc (Brak uśredniania (pojedyncza wartość))[Std odch] | AF2: Pc (Brak uśredniania (pojedyncza wartość))[Min] | AG2: Pc (Brak uśredniania (pojedyncza wartość))[Max] | AH2: Pt[Średnia] | AI2: Pt[Std odch] | AJ2: Pt[Min] | AK2: Pt[Max] | AL2: Pa[Średnia] | AM2: Pa[Std odch] | AN2: Pa[Min] | AO2: Pa[Max] | AP2: Pq[Średnia] | AQ2: Pq[Std odch] | AR2: Pq[Min] | AS2: Pq[Max] | AT2: Psk[Średnia] | AU2: Psk[Std odch] | AV2: Psk[Min] | AW2: Psk[Max] | AX2: Pku[Średnia] | AY2: Pku[Std odch] | AZ2: Pku[Min] | BA2: Pku[Max] | BB2: PSm (Brak uśredniania (pojedyncza wartość))[Średnia] | BC2: PSm (Brak uśredniania (pojedyncza wartość))[Std odch] | BD2: PSm (Brak uśredniania (pojedyncza wartość))[Min] | BE2: PSm (Brak uśredniania (pojedyncza wartość))[Max] | BF2: Pdq[Średnia] | BG2: Pdq[Std odch] | BH2: Pdq[Min] | BI2: Pdq[Max] | BJ2: Pmr (c = 1 µm poniżej najwyższego wypiętrzenia)[Średnia] | BK2: Pmr (c = 1 µm poniżej najwyższego wypiętrzenia)[Std odch] | BL2: Pmr (c = 1 µm poniżej najwyższego wypiętrzenia)[Min] | BM2: Pmr (c = 1 µm poniżej najwyższego wypiętrzenia)[Max] | BN2: Pdc (p = 20%, q = 80%)[Średnia] | BO2: Pdc (p = 20%, q = 80%)[Std odch] | BP2: Pdc (p = 20%, q = 80%)[Min] | BQ2: Pdc (p = 20%, q = 80%)[Max] | BR2: PPc (Brak uśredniania (pojedyncza wartość))[Średnia] | BS2: PPc (Brak uśredniania (pojedyncza wartość))[Std odch] | BT2: PPc (Brak uśredniania (pojedyncza wartość))[Min] | BU2: PPc (Brak uśredniania (pojedyncza wartość))[Max] | BV2: Pp[Średnia] | BW2: Pp[Std odch] | BX2: Pp[Min] | BY2: Pp[Max] | BZ2: Pv[Średnia] | CA2: Pv[Std odch] | CB2: Pv[Min] | CC2: Pv[Max] | CD2: Pz[Średnia] | CE2: Pz[Std odch] | CF2: Pz[Min] | CG2: Pz[Max] | CH2: Pc (Brak uśredniania (pojedyncza wartość))[Średnia] | CI2: Pc (Brak uśredniania (pojedyncza wartość))[Std odch] | CJ2: Pc (Brak uśredniania (pojedyncza wartość))[Min] | CK2: Pc (Brak uśredniania (pojedyncza wartość))[Max] | CL2: Pt[Średnia] | CM2: Pt[Std odch] | CN2: Pt[Min] | CO2: Pt[Max] | CP2: Pa[Średnia] | CQ2: Pa[Std odch] | CR2: Pa[Min] | CS2: Pa[Max] | CT2: Pq[Średnia] | CU2: Pq[Std odch] | CV2: Pq[Min] | CW2: Pq[Max] | CX2: Psk[Średnia] | CY2: Psk[Std odch] | CZ2: Psk[Min] | DA2: Psk[Max] | DB2: Pku[Średnia] | DC2: Pku[Std odch] | DD2: Pku[Min] | DE2: Pku[Max] | DF2: PSm (Brak uśredniania (pojedyncza wartość))[Średnia] | DG2: PSm (Brak uśredniania (pojedyncza wartość))[Std odch] | DH2: PSm (Brak uśredniania (pojedyncza wartość))[Min] | DI2: PSm (Brak uśredniania (pojedyncza wartość))[Max] | DJ2: Pdq[Średnia] | DK2: Pdq[Std odch] | DL2: Pdq[Min] | DM2: Pdq[Max] | DN2: Pmr (c = 1 µm poniżej najwyższego wypiętrzenia)[Średnia] | DO2: Pmr (c = 1 µm poniżej najwyższego wypiętrzenia)[Std odch] | DP2: Pmr (c = 1 µm poniżej najwyższego wypiętrzenia)[Min] | DQ2: Pmr (c = 1 µm poniżej najwyższego wypiętrzenia)[Max] | DR2: Pdc (p = 20%, q = 80%)[Średnia] | DS2: Pdc (p = 20%, q = 80%)[Std odch] | DT2: Pdc (p = 20%, q = 80%)[Min] | DU2: Pdc (p = 20%, q = 80%)[Max] | DV2: PPc (Brak uśredniania (pojedyncza wartość))[Średnia] | DW2: PPc (Brak uśredniania (pojedyncza wartość))[Std odch] | DX2: PPc (Brak uśredniania (pojedyncza wartość))[Min] | DY2: PPc (Brak uśredniania (pojedyncza wartość))[Max] | DZ2: Rp[Średnia] | EA2: Rp[Std odch] | EB2: Rp[Min] | EC2: Rp[Max] | ED2: Rv[Średnia] | EE2: Rv[Std odch] | EF2: Rv[Min] | EG2: Rv[Max] | EH2: Rz[Średnia] | EI2: Rz[Std odch] | EJ2: Rz[Min] | EK2: Rz[Max] | EL2: Rc (Brak uśredniania (pojedyncza wartość))[Średnia] | EM2: Rc (Brak uśredniania (pojedyncza wartość))[Std odch] | EN2: Rc (Brak uśredniania (pojedyncza wartość))[Min] | EO2: Rc (Brak uśredniania (pojedyncza wartość))[Max] | EP2: Rt[Średnia] | EQ2: Rt[Std odch] | ER2: Rt[Min] | ES2: Rt[Max] | ET2: Ra[Średnia] | EU2: Ra[Std odch] | EV2: Ra[Min] | EW2: Ra[Max] | EX2: Rq[Średnia] | EY2: Rq[Std odch] | EZ2: Rq[Min] | FA2: Rq[Max] | FB2: Rsk[Średnia] | FC2: Rsk[Std odch] | FD2: Rsk[Min] | FE2: Rsk[Max] | FF2: Rku[Średnia] | FG2: Rku[Std odch] | FH2: Rku[Min] | FI2: Rku[Max] | FJ2: Rp1max[Średnia] | FK2: Rp1max[Std odch] | FL2: Rp1max[Min] | FM2: Rp1max[Max] | FN2: Rv1max[Średnia] | FO2: Rv1max[Std odch] | FP2: Rv1max[Min] | FQ2: Rv1max[Max] | FR2: Rz1max[Średnia] | FS2: Rz1max[Std odch] | FT2: Rz1max[Min] | FU2: Rz1max[Max] | FV2: Rz(n) (Wskaźnik λc = 1)[Średnia] | FW2: Rz(n) (Wskaźnik λc = 1)[Std odch] | FX2: Rz(n) (Wskaźnik λc = 1)[Min] | FY2: Rz(n) (Wskaźnik λc = 1)[Max] | FZ2: RSm (Brak uśredniania (pojedyncza wartość))[Średnia] | GA2: RSm (Brak uśredniania (pojedyncza wartość))[Std odch] | GB2: RSm (Brak uśredniania (pojedyncza wartość))[Min] | GC2: RSm (Brak uśredniania (pojedyncza wartość))[Max] | GD2: Rdq[Średnia] | GE2: Rdq[Std odch] | GF2: Rdq[Min] | GG2: Rdq[Max] | GH2: Rmr (c = 1 µm poniżej najwyższego wypiętrzenia)[Średnia] | GI2: Rmr (c = 1 µm poniżej najwyższego wypiętrzenia)[Std odch] | GJ2: Rmr (c = 1 µm poniżej najwyższego wypiętrzenia)[Min] | GK2: Rmr (c = 1 µm poniżej najwyższego wypiętrzenia)[Max] | GL2: Rdc (p = 20%, q = 80%)[Średnia] | GM2: Rdc (p = 20%, q = 80%)[Std odch] | GN2: Rdc (p = 20%, q = 80%)[Min] | GO2: Rdc (p = 20%, q = 80%)[Max] | GP2: Rmr (Rz/4) (c = Rz/4 µm powyżej płaszczyzny średniej)[Średnia] | GQ2: Rmr (Rz/4) (c = Rz/4 µm powyżej płaszczyzny średniej)[Std odch] | GR2: Rmr (Rz/4) (c = Rz/4 µm powyżej płaszczyzny średniej)[Min] | GS2: Rmr (Rz/4) (c = Rz/4 µm powyżej płaszczyzny średniej)[Max] | GT2: RPc (Brak uśredniania (pojedyncza wartość))[Średnia] | GU2: RPc (Brak uśredniania (pojedyncza wartość))[Std odch] | GV2: RPc (Brak uśredniania (pojedyncza wartość))[Min] | GW2: RPc (Brak uśredniania (pojedyncza wartość))[Max] | GX2: Rp[Średnia] | GY2: Rp[Std odch] | GZ2: Rp[Min] | HA2: Rp[Max] | HB2: Rv[Średnia] | HC2: Rv[Std odch] | HD2: Rv[Min] | HE2: Rv[Max] | HF2: Rz[Średnia] | HG2: Rz[Std odch] | HH2: Rz[Min] | HI2: Rz[Max] | HJ2: Rc (Brak uśredniania (pojedyncza wartość))[Średnia] | HK2: Rc (Brak uśredniania (pojedyncza wartość))[Std odch] | HL2: Rc (Brak uśredniania (pojedyncza wartość))[Min] | HM2: Rc (Brak uśredniania (pojedyncza wartość))[Max] | HN2: Rt[Średnia] | HO2: Rt[Std odch] | HP2: Rt[Min] | HQ2: Rt[Max] | HR2: Ra[Średnia] | HS2: Ra[Std odch] | HT2: Ra[Min] | HU2: Ra[Max] | HV2: Rq[Średnia] | HW2: Rq[Std odch] | HX2: Rq[Min] | HY2: Rq[Max] | HZ2: Rsk[Średnia] | IA2: Rsk[Std odch] | IB2: Rsk[Min] | IC2: Rsk[Max] | ID2: Rku[Średnia] | IE2: Rku[Std odch] | IF2: Rku[Min] | IG2: Rku[Max] | IH2: Rp1max[Średnia] | II2: Rp1max[Std odch] | IJ2: Rp1max[Min] | IK2: Rp1max[Max] | IL2: Rv1max[Średnia] | IM2: Rv1max[Std odch] | IN2: Rv1max[Min] | IO2: Rv1max[Max] | IP2: Rz1max[Średnia] | IQ2: Rz1max[Std odch] | IR2: Rz1max[Min] | IS2: Rz1max[Max] | IT2: Rz(n) (Wskaźnik λc = 1)[Średnia] | IU2: Rz(n) (Wskaźnik λc = 1)[Std odch] | IV2: Rz(n) (Wskaźnik λc = 1)[Min] | IW2: Rz(n) (Wskaźnik λc = 1)[Max] | IX2: RSm (Brak uśredniania (pojedyncza wartość))[Średnia] | IY2: RSm (Brak uśredniania (pojedyncza wartość))[Std odch] | IZ2: RSm (Brak uśredniania (pojedyncza wartość))[Min] | JA2: RSm (Brak uśredniania (pojedyncza wartość))[Max] | JB2: Rdq[Średnia] | JC2: Rdq[Std odch] | JD2: Rdq[Min] | JE2: Rdq[Max] | JF2: Rmr (c = 1 µm poniżej najwyższego wypiętrzenia)[Średnia] | JG2: Rmr (c = 1 µm poniżej najwyższego wypiętrzenia)[Std odch] | JH2: Rmr (c = 1 µm poniżej najwyższego wypiętrzenia)[Min] | JI2: Rmr (c = 1 µm poniżej najwyższego wypiętrzenia)[Max] | JJ2: Rdc (p = 20%, q = 80%)[Średnia] | JK2: Rdc (p = 20%, q = 80%)[Std odch] | JL2: Rdc (p = 20%, q = 80%)[Min] | JM2: Rdc (p = 20%, q = 80%)[Max] | JN2: Rmr (Rz/4) (c = Rz/4 µm powyżej płaszczyzny średniej)[Średnia] | JO2: Rmr (Rz/4) (c = Rz/4 µm powyżej płaszczyzny średniej)[Std odch] | JP2: Rmr (Rz/4) (c = Rz/4 µm powyżej płaszczyzny średniej)[Min] | JQ2: Rmr (Rz/4) (c = Rz/4 µm powyżej płaszczyzny średniej)[Max] | JR2: RPc (Brak uśredniania (pojedyncza wartość))[Średnia] | JS2: RPc (Brak uśredniania (pojedyncza wartość))[Std odch] | JT2: RPc (Brak uśredniania (pojedyncza wartość))[Min] | JU2: RPc (Brak uśredniania (pojedyncza wartość))[Max] | JV2: Wp[Średnia] | JW2: Wp[Std odch] | JX2: Wp[Min] | JY2: Wp[Max] | JZ2: Wv[Średnia] | KA2: Wv[Std odch] | KB2: Wv[Min] | KC2: Wv[Max] | KD2: Wz[Średnia] | KE2: Wz[Std odch] | KF2: Wz[Min] | KG2: Wz[Max] | KH2: Wc[Średnia] | KI2: Wc[Std odch] | KJ2: Wc[Min] | KK2: Wc[Max] | KL2: Wt[Średnia] | KM2: Wt[Std odch] | KN2: Wt[Min] | KO2: Wt[Max] | KP2: Wa[Średnia] | KQ2: Wa[Std odch] | KR2: Wa[Min] | KS2: Wa[Max] | KT2: Wq[Średnia] | KU2: Wq[Std odch] | KV2: Wq[Min] | KW2: Wq[Max] | KX2: Wsk[Średnia] | KY2: Wsk[Std odch] | KZ2: Wsk[Min] | LA2: Wsk[Max] | LB2: Wku[Średnia] | LC2: Wku[Std odch] | LD2: Wku[Min] | LE2: Wku[Max] | LF2: WSm[Średnia] | LG2: WSm[Std odch] | LH2: WSm[Min] | LI2: WSm[Max] | LJ2: Wdq[Średnia] | LK2: Wdq[Std odch] | LL2: Wdq[Min] | LM2: Wdq[Max] | LN2: Wmr (c = 1 µm poniżej najwyższego wypiętrzenia)[Średnia] | LO2: Wmr (c = 1 µm poniżej najwyższego wypiętrzenia)[Std odch] | LP2: Wmr (c = 1 µm poniżej najwyższego wypiętrzenia)[Min] | LQ2: Wmr (c = 1 µm poniżej najwyższego wypiętrzenia)[Max] | LR2: Wdc (p = 20%, q = 80%)[Średnia] | LS2: Wdc (p = 20%, q = 80%)[Std odch] | LT2: Wdc (p = 20%, q = 80%)[Min] | LU2: Wdc (p = 20%, q = 80%)[Max] | LV2: Wmr (Wz/4)[Średnia] | LW2: Wmr (Wz/4)[Std odch] | LX2: Wmr (Wz/4)[Min] | LY2: Wmr (Wz/4)[Max] | LZ2: WPc[Średnia] | MA2: WPc[Std odch] | MB2: WPc[Min] | MC2: WPc[Max] | MD2: Wp[Średnia] | ME2: Wp[Std odch] | MF2: Wp[Min] | MG2: Wp[Max] | MH2: Wv[Średnia] | MI2: Wv[Std odch] | MJ2: Wv[Min] | MK2: Wv[Max] | ML2: Wz[Średnia] | MM2: Wz[Std odch] | MN2: Wz[Min] | MO2: Wz[Max] | MP2: Wc[Średnia] | MQ2: Wc[Std odch] | MR2: Wc[Min] | MS2: Wc[Max] | MT2: Wt[Średnia] | MU2: Wt[Std odch] | MV2: Wt[Min] | MW2: Wt[Max] | MX2: Wa[Średnia] | MY2: Wa[Std odch] | MZ2: Wa[Min] | NA2: Wa[Max] | NB2: Wq[Średnia] | NC2: Wq[Std odch] | ND2: Wq[Min] | NE2: Wq[Max] | NF2: Wsk[Średnia] | NG2: Wsk[Std odch] | NH2: Wsk[Min] | NI2: Wsk[Max] | NJ2: Wku[Średnia] | NK2: Wku[Std odch] | NL2: Wku[Min] | NM2: Wku[Max] | NN2: WSm[Średnia] | NO2: WSm[Std odch] | NP2: WSm[Min] | NQ2: WSm[Max] | NR2: Wdq[Średnia] | NS2: Wdq[Std odch] | NT2: Wdq[Min] | NU2: Wdq[Max] | NV2: Wmr (c = 1 µm poniżej najwyższego wypiętrzenia)[Średnia] | NW2: Wmr (c = 1 µm poniżej najwyższego wypiętrzenia)[Std odch] | NX2: Wmr (c = 1 µm poniżej najwyższego wypiętrzenia)[Min] | NY2: Wmr (c = 1 µm poniżej najwyższego wypiętrzenia)[Max] | NZ2: Wdc (p = 20%, q = 80%)[Średnia] | OA2: Wdc (p = 20%, q = 80%)[Std odch] | OB2: Wdc (p = 20%, q = 80%)[Min] | OC2: Wdc (p = 20%, q = 80%)[Max] | OD2: Wmr (Wz/4)[Średnia] | OE2: Wmr (Wz/4)[Std odch] | OF2: Wmr (Wz/4)[Min] | OG2: Wmr (Wz/4)[Max] | OH2: WPc[Średnia] | OI2: WPc[Std odch] | OJ2: WPc[Min] | OK2: WPc[Max] | OL2: Sq | OM2: Ssk | ON2: Sku | OO2: Sp | OP2: Sv | OQ2: Sz | OR2: Sa | OS2: Vm (p = 10%) | OT2: Vv (p = 10%) | OU2: Vmp (p = 10%) | OV2: Vmc (p = 10%, q = 80%) | OW2: Vvc (p = 10%, q = 80%) | OX2: Vvv (p = 80%) | OY2: Sk | OZ2: Spk | PA2: Svk | PB2: Smrk1 | PC2: Smrk2 | PD2: Sq | PE2: Ssk | PF2: Sku | PG2: Sp | PH2: Sv | PI2: Sz | PJ2: Sa | PK2: Vm (p = 10%) | PL2: Vv (p = 10%) | PM2: Vmp (p = 10%) | PN2: Vmc (p = 10%, q = 80%) | PO2: Vvc (p = 10%, q = 80%) | PP2: Vvv (p = 80%) | PQ2: Sk | PR2: Spk | PS2: Svk | PT2: Smrk1 | PU2: Smrk2 | PV2: Sk | PW2: Spk | PX2: Svk | PY2: Smrk1 | PZ2: Smrk2 | QA2: Sk | QB2: Spk | QC2: Svk | QD2: Smrk1 | QE2: Smrk2 | QF2: Vmp | QG2: Vmc | QH2: Vvc | QI2: Vvv | QJ2: Vmp | QK2: Vmc | QL2: Vvc | QM2: Vvv | QN2: Izotropię | QO2: Pierwszy kierunek | QP2: Drugi kierunek | QQ2: Trzeci kierunek | QR2: Izotropię | QS2: Pierwszy kierunek | QT2: Drugi kierunek | QU2: Trzeci kierunek
B3: ° | C3: ° | D3: mm² | E3: mm2 | F3: mm2 | G3: % | H3: % | I3: % | J3: mm² | K3: mm² | L3: mm² | M3: mm² | N3: mm² | O3: mm² | P3: mm² | Q3: mm² | R3: µm | S3: µm | T3: µm | U3: µm | V3: µm | W3: µm | X3: µm | Y3: µm | Z3: µm | AA3: µm | AB3: µm | AC3: µm | AD3: µm | AE3: µm | AF3: µm | AG3: µm | AH3: µm | AI3: µm | AJ3: µm | AK3: µm | AL3: µm | AM3: µm | AN3: µm | AO3: µm | AP3: µm | AQ3: µm | AR3: µm | AS3: µm | AT3: <no unit> | AU3: <no unit> | AV3: <no unit> | AW3: <no unit> | AX3: <no unit> | AY3: <no unit> | AZ3: <no unit> | BA3: <no unit> | BB3: mm | BC3: mm | BD3: mm | BE3: mm | BF3: ° | BG3: ° | BH3: ° | BI3: ° | BJ3: % | BK3: % | BL3: % | BM3: % | BN3: µm | BO3: µm | BP3: µm | BQ3: µm | BR3: 1/cm | BS3: 1/cm | BT3: 1/cm | BU3: 1/cm | BV3: µm | BW3: µm | BX3: µm | BY3: µm | BZ3: µm | CA3: µm | CB3: µm | CC3: µm | CD3: µm | CE3: µm | CF3: µm | CG3: µm | CH3: µm | CI3: µm | CJ3: µm | CK3: µm | CL3: µm | CM3: µm | CN3: µm | CO3: µm | CP3: µm | CQ3: µm | CR3: µm | CS3: µm | CT3: µm | CU3: µm | CV3: µm | CW3: µm | CX3: <no unit> | CY3: <no unit> | CZ3: <no unit> | DA3: <no unit> | DB3: <no unit> | DC3: <no unit> | DD3: <no unit> | DE3: <no unit> | DF3: mm | DG3: mm | DH3: mm | DI3: mm | DJ3: ° | DK3: ° | DL3: ° | DM3: ° | DN3: % | DO3: % | DP3: % | DQ3: % | DR3: µm | DS3: µm | DT3: µm | DU3: µm | DV3: 1/cm | DW3: 1/cm | DX3: 1/cm | DY3: 1/cm | DZ3: µm | EA3: µm | EB3: µm | EC3: µm | ED3: µm | EE3: µm | EF3: µm | EG3: µm | EH3: µm | EI3: µm | EJ3: µm | EK3: µm | EL3: µm | EM3: µm | EN3: µm | EO3: µm | EP3: µm | EQ3: µm | ER3: µm | ES3: µm | ET3: µm | EU3: µm | EV3: µm | EW3: µm | EX3: µm | EY3: µm | EZ3: µm | FA3: µm | FB3: <no unit> | FC3: <no unit> | FD3: <no unit> | FE3: <no unit> | FF3: <no unit> | FG3: <no unit> | FH3: <no unit> | FI3: <no unit> | FJ3: µm | FK3: µm | FL3: µm | FM3: µm | FN3: µm | FO3: µm | FP3: µm | FQ3: µm | FR3: µm | FS3: µm | FT3: µm | FU3: µm | FV3: µm | FW3: µm | FX3: µm | FY3: µm | FZ3: mm | GA3: mm | GB3: mm | GC3: mm | GD3: ° | GE3: ° | GF3: ° | GG3: ° | GH3: % | GI3: % | GJ3: % | GK3: % | GL3: µm | GM3: µm | GN3: µm | GO3: µm | GP3: % | GQ3: % | GR3: % | GS3: % | GT3: 1/cm | GU3: 1/cm | GV3: 1/cm | GW3: 1/cm | GX3: µm | GY3: µm | GZ3: µm | HA3: µm | HB3: µm | HC3: µm | HD3: µm | HE3: µm | HF3: µm | HG3: µm | HH3: µm | HI3: µm | HJ3: µm | HK3: µm | HL3: µm | HM3: µm | HN3: µm | HO3: µm | HP3: µm | HQ3: µm | HR3: µm | HS3: µm | HT3: µm | HU3: µm | HV3: µm | HW3: µm | HX3: µm | HY3: µm | HZ3: <no unit> | IA3: <no unit> | IB3: <no unit> | IC3: <no unit> | ID3: <no unit> | IE3: <no unit> | IF3: <no unit> | IG3: <no unit> | IH3: µm | II3: µm | IJ3: µm | IK3: µm | IL3: µm | IM3: µm | IN3: µm | IO3: µm | IP3: µm | IQ3: µm | IR3: µm | IS3: µm | IT3: µm | IU3: µm | IV3: µm | IW3: µm | IX3: mm | IY3: mm | IZ3: mm | JA3: mm | JB3: ° | JC3: ° | JD3: ° | JE3: ° | JF3: % | JG3: % | JH3: % | JI3: % | JJ3: µm | JK3: µm | JL3: µm | JM3: µm | JN3: % | JO3: % | JP3: % | JQ3: % | JR3: 1/cm | JS3: 1/cm | JT3: 1/cm | JU3: 1/cm | JV3: µm | JW3: µm | JX3: µm | JY3: µm | JZ3: µm | KA3: µm | KB3: µm | KC3: µm | KD3: µm | KE3: µm | KF3: µm | KG3: µm | KH3: µm | KI3: µm | KJ3: µm | KK3: µm | KL3: µm | KM3: µm | KN3: µm | KO3: µm | KP3: µm | KQ3: µm | KR3: µm | KS3: µm | KT3: µm | KU3: µm | KV3: µm | KW3: µm | KX3: <no unit> | KY3: <no unit> | KZ3: <no unit> | LA3: <no unit> | LB3: <no unit> | LC3: <no unit> | LD3: <no unit> | LE3: <no unit> | LF3: mm | LG3: mm | LH3: mm | LI3: mm | LJ3: ° | LK3: ° | LL3: ° | LM3: ° | LN3: % | LO3: % | LP3: % | LQ3: % | LR3: µm | LS3: µm | LT3: µm | LU3: µm | LV3: % | LW3: % | LX3: % | LY3: % | LZ3: 1/cm | MA3: 1/cm | MB3: 1/cm | MC3: 1/cm | MD3: µm | ME3: µm | MF3: µm | MG3: µm | MH3: µm | MI3: µm | MJ3: µm | MK3: µm | ML3: µm | MM3: µm | MN3: µm | MO3: µm | MP3: µm | MQ3: µm | MR3: µm | MS3: µm | MT3: µm | MU3: µm | MV3: µm | MW3: µm | MX3: µm | MY3: µm | MZ3: µm | NA3: µm | NB3: µm | NC3: µm | ND3: µm | NE3: µm | NF3: <no unit> | NG3: <no unit> | NH3: <no unit> | NI3: <no unit> | NJ3: <no unit> | NK3: <no unit> | NL3: <no unit> | NM3: <no unit> | NN3: mm | NO3: mm | NP3: mm | NQ3: mm | NR3: ° | NS3: ° | NT3: ° | NU3: ° | NV3: % | NW3: % | NX3: % | NY3: % | NZ3: µm | OA3: µm | OB3: µm | OC3: µm | OD3: % | OE3: % | OF3: % | OG3: % | OH3: 1/cm | OI3: 1/cm | OJ3: 1/cm | OK3: 1/cm | OL3: µm | OM3: <no unit> | ON3: <no unit> | OO3: µm | OP3: µm | OQ3: µm | OR3: µm | OS3: mm³/mm² | OT3: mm³/mm² | OU3: mm³/mm² | OV3: mm³/mm² | OW3: mm³/mm² | OX3: mm³/mm² | OY3: µm | OZ3: µm | PA3: µm | PB3: % | PC3: % | PD3: µm | PE3: <no unit> | PF3: <no unit> | PG3: µm | PH3: µm | PI3: µm | PJ3: µm | PK3: mm³/mm² | PL3: mm³/mm² | PM3: mm³/mm² | PN3: mm³/mm² | PO3: mm³/mm² | PP3: mm³/mm² | PQ3: µm | PR3: µm | PS3: µm | PT3: % | PU3: % | PV3: µm | PW3: µm | PX3: µm | PY3: % | PZ3: % | QA3: µm | QB3: µm | QC3: µm | QD3: % | QE3: % | QF3: mm³/mm² | QG3: mm³/mm² | QH3: mm³/mm² | QI3: mm³/mm² | QJ3: mm³/mm² | QK3: mm³/mm² | QL3: mm³/mm² | QM3: mm³/mm² | QN3: % | QO3: ° | QP3: ° | QQ3: ° | QR3: % | QS3: ° | QT3: ° | QU3: °
A4: C45_5x5\C45_5x5\C45_B\C45_5x5 --- C45_B_x10_conf_blue_5x5.mnt | B4: -1.1296564e-11 | C4: -6.5297481e-13 | D4: 1.3233542 | E4: 1.3830876 | F4: 1.8551465 | G4: 4.0943896 | H4: 4.2792016 | I4: 5.7397274 | J4: 30.997806 | K4: 32.32116 | L4: 32.32116 | M4: 32.32116 | N4: 30.938073 | O4: 32.32116 | P4: 30.466014 | Q4: 32.32116 | R4: 0.77338276 | S4: 0.14986477 | T4: 0.22924058 | U4: 1.1374939 | V4: 0.81000228 | W4: 0.10767866 | X4: 0.51537221 | Y4: 1.0827813 | Z4: 1.583385 | AA4: 0.20070126 | AB4: 0.7467408 | AC4: 1.8437313 | AD4: 0.47018989 | AE4: 0.054454166 | AF4: 0.20422863 | AG4: 0.595878 | AH4: 1.583385 | AI4: 0.20070126 | AJ4: 0.7467408 | AK4: 1.8437313 | AL4: 0.15971602 | AM4: 0.020110865 | AN4: 0.092767242 | AO4: 0.19827355 | AP4: 0.20316413 | AQ4: 0.024933368 | AR4: 0.11862026 | AS4: 0.24992536 | AT4: -0.17850123 | AU4: 0.1484718 | AV4: -0.60411711 | AW4: 0.28460394 | AX4: 3.4428423 | AY4: 0.27593901 | AZ4: 2.9267614 | BA4: 4.2287805 | BB4: 0.047913113 | BC4: 0.08125874 | BD4: 0.029135493 | BE4: 1.07088 | BF4: 2.6635429 | BG4: 0.44823375 | BH4: 0.16257619 | BI4: 3.4314926 | BJ4: 81.792463 | BK4: 14.854491 | BL4: 23.608307 | BM4: 100 | BN4: 0.33062378 | BO4: 0.04366956 | BP4: 0.17818893 | BQ4: 0.40834796 | BR4: 254.16376 | BS4: 42.464377 | BT4: 9.3381145 | BU4: 343.22399 | BV4: 0.60203854 | BW4: 0.12061002 | BX4: 0.20083657 | BY4: 0.79460699 | BZ4: 0.62382136 | CA4: 0.10566895 | CB4: 0.28265739 | CC4: 0.87540196 | CD4: 1.2258599 | CE4: 0.12773493 | CF4: 0.5002093 | CG4: 1.3143941 | CH4: 0.44203383 | CI4: 0.051252736 | CJ4: 0.2056217 | CK4: 0.53913161 | CL4: 1.2258599 | CM4: 0.12773493 | CN4: 0.5002093 | CO4: 1.3143941 | CP4: 0.15716269 | CQ4: 0.021690542 | CR4: 0.075258494 | CS4: 0.19523129 | CT4: 0.19761641 | CU4: 0.026532161 | CV4: 0.096855228 | CW4: 0.24243291 | CX4: -0.15817841 | CY4: 0.18778048 | CZ4: -0.75894088 | DA4: 0.42208311 | DB4: 3.0520551 | DC4: 0.25815202 | DD4: 2.6324208 | DE4: 4.198271 | DF4: 0.05075127 | DG4: 0.13624034 | DH4: 0.02817448 | DI4: 1.81746 | DJ4: 2.5903315 | DK4: 0.44055095 | DL4: 0.040963913 | DM4: 3.2753897 | DN4: 95.185804 | DO4: 3.8134943 | DP4: 83.712884 | DQ4: 100 | DR4: 0.32897462 | DS4: 0.047791001 | DT4: 0.13737585 | DU4: 0.40825123 | DV4: 267.91075 | DW4: 44.287095 | DX4: 5.5021844 | DY4: 354.93113 | DZ4: 0.51979896 | EA4: 0.096024963 | EB4: 0.039349282 | EC4: 0.69294044 | ED4: 0.58068751 | EE4: 0.10116292 | EF4: 0.080795732 | EG4: 0.78890472 | EH4: 1.1004865 | EI4: 0.18337425 | EJ4: 0.12014501 | EK4: 1.4142548 | EL4: 0.43036887 | EM4: 0.055009697 | EN4: 0.11076085 | EO4: 0.55513067 | EP4: 1.4929781 | EQ4: 0.24318596 | ER4: 0.3505172 | ES4: 1.9222731 | ET4: 0.13147468 | EU4: 0.02017105 | EV4: 0.020964701 | EW4: 0.16293174 | EX4: 0.16928394 | EY4: 0.026092738 | EZ4: 0.026961512 | FA4: 0.21235881 | FB4: -0.21746263 | FC4: 0.17198999 | FD4: -0.59514107 | FE4: 0.20918749 | FF4: 3.7851335 | FG4: 0.3422472 | FH4: 3.0848032 | FI4: 4.9212155 | FJ4: 0.72720008 | FK4: 0.15645779 | FL4: 0.073931225 | FM4: 1.1026493 | FN4: 0.76577799 | FO4: 0.13629922 | FP4: 0.27658597 | FQ4: 1.1529853 | FR4: 1.383197 | FS4: 0.22599445 | FT4: 0.3123008 | FU4: 1.9133676 | FV4: 1.1445779 | FW4: 0.26595363 | FX4: 0.0425466 | FY4: 1.9133676 | FZ4: 0.036448545 | GA4: 0.034024099 | GB4: 0.024778393 | GC4: 0.41745 | GD4: 2.6081316 | GE4: 0.46120291 | GF4: 0.094120111 | GG4: 3.3822136 | GH4: 88.207352 | GI4: 14.051918 | GJ4: 23.830621 | GK4: 100 | GL4: 0.26617975 | GM4: 0.042772438 | GN4: 0.036120797 | GO4: 0.33262931 | GP4: 4.4110372 | GQ4: 1.1381671 | GR4: 2.068456 | GS4: 12.442539 | GT4: 308.65237 | GU4: 47.437427 | GV4: 23.954965 | GW4: 403.57743 | GX4: 0.46308074 | GY4: 0.088660432 | GZ4: 0.025813863 | HA4: 0.58788588 | HB4: 0.51873615 | HC4: 0.092522277 | HD4: 0.049708022 | HE4: 0.72156459 | HF4: 0.98181689 | HG4: 0.15943194 | HH4: 0.075521886 | HI4: 1.2076587 | HJ4: 0.40948218 | HK4: 0.057243294 | HL4: 0.055492317 | HM4: 0.522246 | HN4: 1.2362436 | HO4: 0.17356585 | HP4: 0.1605473 | HQ4: 1.5694646 | HR4: 0.12939248 | HS4: 0.020988402 | HT4: 0.01418096 | HU4: 0.15799269 | HV4: 0.16457488 | HW4: 0.026631141 | HX4: 0.018536327 | HY4: 0.20036531 | HZ4: -0.21042036 | IA4: 0.18134902 | IB4: -0.69374499 | IC4: 0.26134604 | ID4: 3.3563251 | IE4: 0.26143911 | IF4: 2.9635955 | IG4: 4.5633455 | IH4: 0.59719633 | II4: 0.12357644 | IJ4: 0.037995378 | IK4: 0.84361007 | IL4: 0.63904729 | IM4: 0.11335982 | IN4: 0.12255192 | IO4: 0.92901417 | IP4: 1.1552209 | IQ4: 0.15299574 | IR4: 0.1505766 | IS4: 1.3762475 | IT4: 1.0191407 | IU4: 0.20434668 | IV4: 0.0335266 | IW4: 1.3236706 | IX4: 0.035082466 | IY4: 0.030592134 | IZ4: 0.024450925 | JA4: 0.357995 | JB4: 2.5426531 | JC4: 0.45356844 | JD4: 0.027851987 | JE4: 3.2205028 | JF4: 96.977594 | JG4: 3.404009 | JH4: 81.287131 | JI4: 100 | JJ4: 0.26524758 | JK4: 0.045196318 | JL4: 0.024183775 | JM4: 0.33051283 | JN4: 5.9483411 | JO4: 1.0768556 | JP4: 3.2258065 | JQ4: 11.524255 | JR4: 319.30066 | JS4: 49.015785 | JT4: 27.933351 | JU4: 408.98248 | JV4: 0.18613574 | JW4: 0.047083865 | JX4: 0.087750483 | JY4: 0.28637145 | JZ4: 0.20202288 | KA4: 0.055602981 | KB4: 0.060926817 | KC4: 0.31991189 | KD4: 0.38815862 | KE4: 0.083960366 | KF4: 0.1486773 | KG4: 0.5818241 | KH4: 0.24600482 | KI4: 0.061271285 | KJ4: 0.09714445 | KK4: 0.4491143 | KL4: 0.38815862 | KM4: 0.083960366 | KN4: 0.1486773 | KO4: 0.5818241 | KP4: 0.076808374 | KQ4: 0.016718429 | KR4: 0.038951393 | KS4: 0.12075968 | KT4: 0.095676482 | KU4: 0.019676508 | KV4: 0.043802976 | KW4: 0.14847645 | KX4: -0.16499579 | KY4: 0.53656886 | KZ4: -1.7873308 | LA4: 1.0052128 | LB4: 2.7835472 | LC4: 0.81985916 | LD4: 1.7664708 | LE4: 6.1287764 | LF4: 1.8195482 | LG4: 0.5632919 | LH4: 0.94806 | LI4: 3.66942 | LJ4: 0.017258728 | LK4: 0.0038503376 | LL4: 0.009091749 | LM4: 0.027594075 | LN4: 100 | LO4: 0 | LP4: 100 | LQ4: 100 | LR4: 0.16239441 | LS4: 0.043844678 | LT4: 0.078909868 | LU4: 0.28706333 | LV4: 15.830784 | LW4: 5.1831413 | LX4: 4.1574525 | LY4: 27.863777 | LZ4: 5.9139867 | MA4: 1.4408042 | MB4: 2.7252263 | MC4: 10.547856 | MD4: 0.18290058 | ME4: 0.04755904 | MF4: 0.081851048 | MG4: 0.28342238 | MH4: 0.19628459 | MI4: 0.054191026 | MJ4: 0.058413444 | MK4: 0.30301333 | ML4: 0.37918516 | MM4: 0.083590444 | MN4: 0.1406299 | MO4: 0.5626957 | MP4: 0.24242389 | MQ4: 0.065103529 | MR4: 0.08649695 | MS4: 0.496654 | MT4: 0.37918516 | MU4: 0.083590444 | MV4: 0.1406299 | MW4: 0.5626957 | MX4: 0.075287117 | MY4: 0.016801181 | MZ4: 0.037007756 | NA4: 0.11993353 | NB4: 0.093686942 | NC4: 0.019723987 | ND4: 0.041617971 | NE4: 0.14747576 | NF4: -0.15074445 | NG4: 0.53498426 | NH4: -1.7873308 | NI4: 1.0042149 | NJ4: 2.767312 | NK4: 0.81371784 | NL4: 1.7847946 | NM4: 6.1287764 | NN4: 1.8311374 | NO4: 0.5938199 | NP4: 0.95772 | NQ4: 4.38564 | NR4: 0.016921513 | NS4: 0.0039248787 | NT4: 0.0077744581 | NU4: 0.027255323 | NV4: 100 | NW4: 0 | NX4: 100 | NY4: 100 | NZ4: 0.15934704 | OA4: 0.043851279 | OB4: 0.071729376 | OC4: 0.28614941 | OD4: 15.998534 | OE4: 5.1999883 | OF4: 4.1574525 | OG4: 27.885891 | OH4: 5.901124 | OI4: 1.4561319 | OJ4: 2.2801689 | OK4: 10.441465 | OL4: 0.17793514 | OM4: -0.23820775 | ON4: 4.0549582 | OO4: 1.252787 | OP4: 1.1107315 | OQ4: 2.3635185 | OR4: 0.13691071 | OS4: 8.8426989e-06 | OT4: 0.00022158844 | OU4: 8.8426989e-06 | OV4: 0.00015050172 | OW4: 0.00019804098 | OX4: 2.354746e-05 | OY4: 0.41459509 | OZ4: 0.17695099 | PA4: 0.22402383 | PB4: 9.9428703 | PC4: 88.116489 | PD4: 0.1728159 | PE4: -0.22288335 | PF4: 3.4690035 | PG4: 0.9452092 | PH4: 0.9519834 | PI4: 1.8971926 | PJ4: 0.13480971 | PK4: 8.0888168e-06 | PL4: 0.00021950489 | PM4: 8.0888168e-06 | PN4: 0.00014978631 | PO4: 0.00019692039 | PP4: 2.2584505e-05 | PQ4: 0.41472027 | PR4: 0.16173931 | PS4: 0.20892676 | PT4: 9.8178919 | PU4: 88.269729 | PV4: 0.63954945 | PW4: 0.24233431 | PX4: 0.24406294 | PY4: 9.7811301 | PZ4: 89.38827 | QA4: 0.63922486 | QB4: 0.22263929 | QC4: 0.21610519 | QD4: 9.7934696 | QE4: 89.579908 | QF4: 1.21576e-05 | QG4: 0.00022627379 | QH4: 0.00030205981 | QI4: 2.9150193e-05 | QJ4: 1.1194739e-05 | QK4: 0.00022631947 | QL4: 0.00030198163 | QM4: 2.7393549e-05 | QN4: ***** | QO4: 89.979489 | QP4: 120.98924 | QQ4: 104.77319 | QR4: ***** | QS4: 89.980216 | QT4: 120.98627 | QU4: 104.77485
A5: C45_5x5\C45_5x5\C45_B\C45_5x5 --- C45_B_x10_conf_green_5x5.mnt | B5: -1.038078e-11 | C5: 3.6011019e-12 | D5: 0.0041782536 | E5: 0.063864054 | F5: 0.53142472 | G5: 0.012834987 | H5: 0.19618108 | I5: 1.6324594 | J5: 32.549447 | K5: 32.553625 | L5: 32.553625 | M5: 32.553625 | N5: 32.489761 | O5: 32.553625 | P5: 32.0222 | Q5: 32.553625 | R5: 0.80086791 | S5: 0.13982153 | T5: 0.50393458 | U5: 1.1218802 | V5: 1.0031107 | W5: 0.14143575 | X5: 0.62868833 | Y5: 1.3794814 | Z5: 1.8039786 | AA5: 0.19207434 | AB5: 1.145103 | AC5: 2.095038 | AD5: 0.54008132 | AE5: 0.051791679 | AF5: 0.40210144 | AG5: 0.64416603 | AH5: 1.8039786 | AI5: 0.19207434 | AJ5: 1.145103 | AK5: 2.095038 | AL5: 0.17933656 | AM5: 0.020129469 | AN5: 0.13206816 | AO5: 0.23355441 | AP5: 0.22958203 | AQ5: 0.024422444 | AR5: 0.16904156 | AS5: 0.29200029 | AT5: -0.25229707 | AU5: 0.14796425 | AV5: -0.72198482 | AW5: 0.15562394 | AX5: 3.6598021 | AY5: 0.43107155 | AZ5: 2.7645875 | BA5: 5.0003655 | BB5: 0.043130286 | BC5: 0.005522662 | BD5: 0.034460115 | BE5: 0.073026353 | BF5: 2.7894406 | BG5: 0.27227777 | BH5: 1.9685289 | BI5: 3.4290592 | BJ5: 77.859485 | BK5: 16.269285 | BL5: 30.76026 | BM5: 99.469261 | BN5: 0.36892926 | BO5: 0.04539492 | BP5: 0.27168386 | BQ5: 0.48760263 | BR5: 235.14419 | BS5: 26.33863 | BT5: 136.93687 | BU5: 290.19055 | BV5: 0.67880228 | BW5: 0.13828609 | BX5: 0.31156676 | BY5: 0.95865744 | BZ5: 0.74538482 | CA5: 0.12359061 | CB5: 0.49970572 | CC5: 1.0448132 | CD5: 1.4241871 | CE5: 0.092087675 | CF5: 0.941886 | CG5: 1.506652 | CH5: 0.51127939 | CI5: 0.04626373 | CJ5: 0.37408981 | CK5: 0.59768192 | CL5: 1.4241871 | CM5: 0.092087675 | CN5: 0.941886 | CO5: 1.506652 | CP5: 0.17725057 | CQ5: 0.019789917 | CR5: 0.13194536 | CS5: 0.23072964 | CT5: 0.2241992 | CU5: 0.023478521 | CV5: 0.16849652 | CW5: 0.28482402 | CX5: -0.17995646 | CY5: 0.1654791 | CZ5: -0.69032472 | DA5: 0.20579557 | DB5: 3.1871386 | DC5: 0.29763551 | DD5: 2.5539751 | DE5: 3.9771872 | DF5: 0.041044191 | DG5: 0.0052578836 | DH5: 0.032577049 | DI5: 0.071331724 | DJ5: 2.7229614 | DK5: 0.25566428 | DL5: 1.9484942 | DM5: 3.3115653 | DN5: 88.949104 | DO5: 8.186047 | DP5: 58.509534 | DQ5: 100 | DR5: 0.36884122 | DS5: 0.045345421 | DT5: 0.27173969 | DU5: 0.48768031 | DV5: 247.0618 | DW5: 27.414336 | DX5: 140.19008 | DY5: 306.96457 | DZ5: 0.5719456 | EA5: 0.080009214 | EB5: 0.40478484 | EC5: 0.75265429 | ED5: 0.70856967 | EE5: 0.086959767 | EF5: 0.47217248 | EG5: 0.98227705 | EH5: 1.2805153 | EI5: 0.14179052 | EJ5: 0.96142 | EK5: 1.5447887 | EL5: 0.49960186 | EM5: 0.048807691 | EN5: 0.36650821 | EO5: 0.60323145 | EP5: 1.7178143 | EQ5: 0.21282741 | ER5: 1.147896 | ES5: 2.160111 | ET5: 0.15090834 | EU5: 0.014131822 | EV5: 0.10506051 | EW5: 0.17328247 | EX5: 0.19570794 | EY5: 0.018816391 | EZ5: 0.1392133 | FA5: 0.22605689 | FB5: -0.29062689 | FC5: 0.1651163 | FD5: -0.76849307 | FE5: 0.13336352 | FF5: 3.9636684 | FG5: 0.43327538 | FH5: 2.8841538 | FI5: 5.7016833 | FJ5: 0.77327149 | FK5: 0.14821632 | FL5: 0.42820446 | FM5: 1.1164543 | FN5: 0.94454281 | FO5: 0.13776625 | FP5: 0.61056006 | FQ5: 1.4065703 | FR5: 1.6244939 | FS5: 0.21474882 | FT5: 1.067482 | FU5: 2.008926 | FV5: 1.3992757 | FW5: 0.25040559 | FX5: 0.906704 | FY5: 1.99964 | FZ5: 0.034775032 | GA5: 0.0023624449 | GB5: 0.02751802 | GC5: 0.041700902 | GD5: 2.785676 | GE5: 0.27681512 | GF5: 1.9738685 | GG5: 3.4612962 | GH5: 82.671704 | GI5: 16.888269 | GJ5: 25.635666 | GK5: 99.852253 | GL5: 0.30198104 | GM5: 0.028084537 | GN5: 0.20814036 | GO5: 0.35553475 | GP5: 4.4445204 | GQ5: 0.98007859 | GR5: 2.2334116 | GS5: 8.1260773 | GT5: 288.90111 | GU5: 19.800489 | GV5: 239.80297 | GW5: 363.39824 | GX5: 0.53423231 | GY5: 0.079477081 | GZ5: 0.31144781 | HA5: 0.69947977 | HB5: 0.61587946 | HC5: 0.073256709 | HD5: 0.46599051 | HE5: 0.83962651 | HF5: 1.1501118 | HG5: 0.10243686 | HH5: 0.83725414 | HI5: 1.3470143 | HJ5: 0.47699087 | HK5: 0.043438837 | HL5: 0.35613557 | HM5: 0.55394502 | HN5: 1.4383234 | HO5: 0.12775527 | HP5: 0.998011 | HQ5: 1.714088 | HR5: 0.1488926 | HS5: 0.013577941 | HT5: 0.10474894 | HU5: 0.17075093 | HV5: 0.19067422 | HW5: 0.017339446 | HX5: 0.13780024 | HY5: 0.21831705 | HZ5: -0.22733265 | IA5: 0.18310963 | IB5: -0.69510263 | IC5: 0.19966779 | ID5: 3.5202407 | IE5: 0.30740709 | IF5: 2.8516425 | IG5: 4.5285769 | IH5: 0.68957015 | II5: 0.11973573 | IJ5: 0.37395229 | IK5: 0.95035899 | IL5: 0.74875328 | IM5: 0.10616614 | IN5: 0.51659679 | IO5: 1.0419144 | IP5: 1.3574289 | IQ5: 0.11449772 | IR5: 0.937574 | IS5: 1.606584 | IT5: 1.2379647 | IU5: 0.147432 | IV5: 0.856434 | IW5: 1.507357 | IX5: 0.033579226 | IY5: 0.0021635337 | IZ5: 0.026983689 | JA5: 0.041072889 | JB5: 2.7236925 | JC5: 0.26297775 | JD5: 1.9532407 | JE5: 3.3605499 | JF5: 91.173288 | JG5: 8.2050055 | JH5: 60.688795 | JI5: 100 | JJ5: 0.30189424 | JK5: 0.028135616 | JL5: 0.20826686 | JM5: 0.35459778 | JN5: 5.8046363 | JO5: 1.1899257 | JP5: 2.7086924 | JQ5: 9.8190193 | JR5: 299.04954 | JS5: 19.43855 | JT5: 243.46961 | JU5: 370.59425 | JV5: 0.20347783 | JW5: 0.066598524 | JX5: 0.082603695 | JY5: 0.36733834 | JZ5: 0.21249829 | KA5: 0.058212594 | KB5: 0.093115155 | KC5: 0.36902055 | KD5: 0.41597612 | KE5: 0.10287894 | KF5: 0.224474 | KG5: 0.667695 | KH5: 0.26983968 | KI5: 0.085694485 | KJ5: 0.078757333 | KK5: 0.51257 | KL5: 0.41597612 | KM5: 0.10287894 | KN5: 0.224474 | KO5: 0.667695 | KP5: 0.084103791 | KQ5: 0.022419706 | KR5: 0.046150479 | KS5: 0.14191938 | KT5: 0.10363346 | KU5: 0.025797271 | KV5: 0.059018233 | KW5: 0.1665015 | KX5: -0.13862861 | KY5: 0.53861247 | KZ5: -1.5872793 | LA5: 1.0618754 | LB5: 2.7185162 | LC5: 0.67556126 | LD5: 1.7185462 | LE5: 5.5174753 | LF5: 1.7940006 | LG5: 0.58084032 | LH5: 0.52854 | LI5: 3.58248 | LJ5: 0.018909281 | LK5: 0.0055483164 | LL5: 0.010769303 | LM5: 0.035686568 | LN5: 100 | LO5: 0 | LP5: 100 | LQ5: 100 | LR5: 0.18000338 | LS5: 0.055283929 | LT5: 0.079196117 | LU5: 0.3325004 | LV5: 16.764634 | LW5: 5.2610091 | LX5: 5.2631579 | LY5: 29.015994 | LZ5: 6.0825297 | MA5: 1.8382708 | MB5: 2.7913624 | MC5: 18.920044 | MD5: 0.20044015 | ME5: 0.065856476 | MF5: 0.081212108 | MG5: 0.36669087 | MH5: 0.2083489 | MI5: 0.056797293 | MJ5: 0.092232226 | MK5: 0.34784199 | ML5: 0.40878905 | MM5: 0.10099355 | MN5: 0.223981 | MO5: 0.643284 | MP5: 0.26460371 | MQ5: 0.082572864 | MR5: 0.078520667 | MS5: 0.486301 | MT5: 0.40878905 | MU5: 0.10099355 | MV5: 0.223981 | MW5: 0.643284 | MX5: 0.083037162 | MY5: 0.022216751 | MZ5: 0.046121014 | NA5: 0.14025342 | NB5: 0.10220548 | NC5: 0.025546441 | ND5: 0.058924665 | NE5: 0.16378065 | NF5: -0.13387035 | NG5: 0.53610183 | NH5: -1.5238909 | NI5: 1.0722296 | NJ5: 2.7016629 | NK5: 0.66951774 | NL5: 1.7158187 | NM5: 5.5302972 | NN5: 1.7910074 | NO5: 0.57936632 | NP5: 0.50508 | NQ5: 3.59904 | NR5: 0.018616925 | NS5: 0.0054988877 | NT5: 0.010678435 | NU5: 0.035139979 | NV5: 100 | NW5: 0 | NX5: 100 | NY5: 100 | NZ5: 0.17783787 | OA5: 0.054837732 | OB5: 0.079312777 | OC5: 0.33038233 | OD5: 16.902566 | OE5: 5.2674185 | OF5: 5.3295002 | OG5: 29.721362 | OH5: 6.094251 | OI5: 1.8691313 | OJ5: 2.7785187 | OK5: 19.798844 | OL5: 0.20173095 | OM5: -0.3281121 | ON5: 4.3109941 | OO5: 1.224416 | OP5: 1.453828 | OQ5: 2.678244 | OR5: 0.15394258 | OS5: 1.0151994e-05 | OT5: 0.00024944151 | OU5: 1.0151994e-05 | OV5: 0.00016783059 | OW5: 0.00022209141 | OX5: 2.7350094e-05 | OY5: 0.4585852 | OZ5: 0.20361886 | PA5: 0.26701121 | PB5: 10.213547 | PC5: 87.888386 | PD5: 0.19639564 | PE5: -0.22889921 | PF5: 3.6199456 | PG5: 1.071014 | PH5: 1.14207 | PI5: 2.213084 | PJ5: 0.15215465 | PK5: 9.5476153e-06 | PL5: 0.00024785922 | PM5: 9.5476153e-06 | PN5: 0.00016801977 | PO5: 0.00022177523 | PP5: 2.608399e-05 | PQ5: 0.45948655 | PR5: 0.19150017 | PS5: 0.24609637 | PT5: 10.137029 | PU5: 87.911525 | PV5: 0.69483467 | PW5: 0.27870546 | PX5: 0.2997384 | PY5: 11.349175 | PZ5: 89.89167 | QA5: 0.6947897 | QB5: 0.26607363 | QC5: 0.27372608 | QD5: 11.34981 | QE5: 89.890971 | QF5: 1.3433826e-05 | QG5: 0.00024866301 | QH5: 0.00034771699 | QI5: 3.2827677e-05 | QJ5: 1.2728545e-05 | QK5: 0.00024863608 | QL5: 0.00034761392 | QM5: 3.1511584e-05 | QN5: ***** | QO5: 89.978399 | QP5: 81.245464 | QQ5: 105.73662 | QR5: ***** | QS5: 89.975549 | QT5: 101.98565 | QU5: 81.244335
A6: C45_5x5\C45_5x5\C45_B\C45_5x5 --- C45_B_x10_conf_red_5x5.mnt | B6: -1.524014e-11 | C6: 1.0772658e-11 | D6: 0.0052732836 | E6: 0.064319205 | F6: 0.54481456 | G6: 0.01619876 | H6: 0.19757924 | I6: 1.6735911 | J6: 32.548352 | K6: 32.553625 | L6: 32.553625 | M6: 32.553625 | N6: 32.489306 | O6: 32.553625 | P6: 32.00881 | Q6: 32.553625 | R6: 0.96722958 | S6: 0.16128727 | T6: 0.56097417 | U6: 1.3116257 | V6: 1.2581822 | W6: 0.16675397 | X6: 0.88438343 | Y6: 1.7288814 | Z6: 2.2254118 | AA6: 0.20788046 | AB6: 1.604667 | AC6: 2.51101 | AD6: 0.65541317 | AE6: 0.058432663 | AF6: 0.49434382 | AG6: 0.75742217 | AH6: 2.2254118 | AI6: 0.20788046 | AJ6: 1.604667 | AK6: 2.51101 | AL6: 0.21163836 | AM6: 0.02254024 | AN6: 0.15320138 | AO6: 0.28419411 | AP6: 0.27391344 | AQ6: 0.027597651 | AR6: 0.19968749 | AS6: 0.35614049 | AT6: -0.25446178 | AU6: 0.17919373 | AV6: -0.76768772 | AW6: 0.17958546 | AX6: 3.9577628 | AY6: 0.48650968 | AZ6: 2.8571659 | BA6: 5.1012779 | BB6: 0.039788546 | BC6: 0.0055856674 | BD6: 0.031205056 | BE6: 0.073764285 | BF6: 3.5613343 | BG6: 0.36395857 | BH6: 2.4000795 | BI6: 4.3356686 | BJ6: 54.49798 | BK6: 22.501429 | BL6: 10.968598 | BM6: 96.572313 | BN6: 0.42987237 | BO6: 0.051175423 | BP6: 0.307855 | BQ6: 0.58990903 | BR6: 255.52309 | BS6: 30.700157 | BT6: 135.56696 | BU6: 320.46089 | BV6: 0.79292544 | BW6: 0.1519165 | BX6: 0.42751723 | BY6: 1.0861316 | BZ6: 0.89912306 | CA6: 0.13602537 | CB6: 0.63134285 | CC6: 1.2888864 | CD6: 1.6920485 | CE6: 0.072521669 | CF6: 1.361627 | CG6: 1.764531 | CH6: 0.61674343 | CI6: 0.049869965 | CJ6: 0.48251776 | CK6: 0.70864903 | CL6: 1.6920485 | CM6: 0.072521669 | CN6: 1.361627 | CO6: 1.764531 | CP6: 0.20884503 | CQ6: 0.021910402 | CR6: 0.15245107 | CS6: 0.28024511 | CT6: 0.26622624 | CU6: 0.025697034 | CV6: 0.19823941 | CW6: 0.34611996 | CX6: -0.15995279 | CY6: 0.18758499 | CZ6: -0.74961799 | DA6: 0.23183802 | DB6: 3.3190926 | DC6: 0.31256091 | DD6: 2.6577224 | DE6: 4.2438769 | DF6: 0.037650796 | DG6: 0.0051606408 | DH6: 0.028929687 | DI6: 0.066610968 | DJ6: 3.463705 | DK6: 0.33519497 | DL6: 2.3428107 | DM6: 4.1992207 | DN6: 75.678357 | DO6: 14.706192 | DP6: 37.021382 | DQ6: 99.226006 | DR6: 0.42976942 | DS6: 0.051116256 | DT6: 0.3077471 | DU6: 0.58997764 | DV6: 269.95745 | DW6: 32.542106 | DX6: 150.12543 | DY6: 345.66568 | DZ6: 0.70630356 | EA6: 0.09823955 | EB6: 0.44269551 | EC6: 0.94438057 | ED6: 0.89571865 | EE6: 0.10616352 | EF6: 0.62518162 | EG6: 1.2092185 | EH6: 1.6020222 | EI6: 0.1723007 | EJ6: 1.1530743 | EK6: 1.963076 | EL6: 0.6140241 | EM6: 0.057814584 | EN6: 0.45574036 | EO6: 0.75818737 | EP6: 2.1461412 | EQ6: 0.23609345 | ER6: 1.473509 | ES6: 2.5814 | ET6: 0.18312845 | EU6: 0.016450143 | EV6: 0.12698072 | EW6: 0.2228383 | EX6: 0.23974919 | EY6: 0.022642784 | EZ6: 0.17241657 | FA6: 0.29527543 | FB6: -0.28650887 | FC6: 0.1750955 | FD6: -0.77725232 | FE6: 0.33167475 | FF6: 4.1869624 | FG6: 0.46561691 | FH6: 3.1697281 | FI6: 6.2470419 | FJ6: 0.9437735 | FK6: 0.16457538 | FL6: 0.55738708 | FM6: 1.2963482 | FN6: 1.2023677 | FO6: 0.16196722 | FP6: 0.71547625 | FQ6: 1.5984434 | FR6: 2.0416154 | FS6: 0.23168848 | FT6: 1.361325 | FU6: 2.435272 | FV6: 1.7593356 | FW6: 0.28443523 | FX6: 1.115473 | FY6: 2.377067 | FZ6: 0.032926864 | GA6: 0.002344258 | GB6: 0.0278553 | GC6: 0.038941267 | GD6: 3.5673442 | GE6: 0.37311838 | GF6: 2.4240126 | GG6: 4.3488717 | GH6: 58.813528 | GI6: 24.497125 | GJ6: 10.982517 | GK6: 98.719527 | GL6: 0.36038753 | GM6: 0.030499998 | GN6: 0.24388547 | GO6: 0.42830368 | GP6: 4.3617598 | GQ6: 0.84736796 | GR6: 2.2408274 | GS6: 6.9441024 | GT6: 305.25354 | GU6: 21.865959 | GV6: 256.79698 | GW6: 358.99811 | GX6: 0.64918291 | GY6: 0.089021946 | GZ6: 0.40883924 | HA6: 0.81794211 | HB6: 0.75853485 | HC6: 0.075564775 | HD6: 0.59670832 | HE6: 0.9636298 | HF6: 1.4077177 | HG6: 0.10495271 | HH6: 1.0686903 | HI6: 1.6336613 | HJ6: 0.58246263 | HK6: 0.048962215 | HL6: 0.42136272 | HM6: 0.70721042 | HN6: 1.735903 | HO6: 0.12004924 | HP6: 1.340185 | HQ6: 2.018444 | HR6: 0.18030976 | HS6: 0.015353032 | HT6: 0.12606248 | HU6: 0.21739792 | HV6: 0.23236173 | HW6: 0.019827438 | HX6: 0.1680269 | HY6: 0.27719331 | HZ6: -0.20524613 | IA6: 0.17012834 | IB6: -0.75532193 | IC6: 0.15963257 | ID6: 3.6077236 | IE6: 0.29737312 | IF6: 2.883357 | IG6: 4.5676093 | IH6: 0.8249195 | II6: 0.12636938 | IJ6: 0.50663381 | IK6: 1.1329494 | IL6: 0.91098354 | IM6: 0.11682616 | IN6: 0.64187666 | IO6: 1.2787669 | IP6: 1.642728 | IQ6: 0.10041284 | IR6: 1.333014 | IS6: 1.843025 | IT6: 1.5154942 | IU6: 0.14044933 | IV6: 1.115472 | IW6: 1.771237 | IX6: 0.031649746 | IY6: 0.0023226811 | IZ6: 0.026038591 | JA6: 0.037607347 | JB6: 3.4735337 | JC6: 0.34688189 | JD6: 2.3669516 | JE6: 4.2320875 | JF6: 75.985371 | JG6: 15.643895 | JH6: 27.014411 | JI6: 98.818025 | JJ6: 0.36056731 | JK6: 0.030493115 | JL6: 0.2439219 | JM6: 0.42695207 | JN6: 5.9801707 | JO6: 1.0210577 | JP6: 3.1026841 | JQ6: 9.1142841 | JR6: 317.68102 | JS6: 23.581741 | JT6: 265.90549 | JU6: 384.04535 | JV6: 0.21486898 | JW6: 0.070630986 | JX6: 0.087718933 | JY6: 0.42522738 | JZ6: 0.23810576 | KA6: 0.068995866 | KB6: 0.09517513 | KC6: 0.41468032 | KD6: 0.45297474 | KE6: 0.1181483 | KF6: 0.226218 | KG6: 0.73872 | KH6: 0.29361505 | KI6: 0.10562525 | KJ6: 0.092946 | KK6: 0.56340167 | KL6: 0.45297474 | KM6: 0.1181483 | KN6: 0.226218 | KO6: 0.73872 | KP6: 0.091383932 | KQ6: 0.028125284 | KR6: 0.044360648 | KS6: 0.17548076 | KT6: 0.11236435 | KU6: 0.03138207 | KV6: 0.055863893 | KW6: 0.19776008 | KX6: -0.23764385 | KY6: 0.53535538 | KZ6: -1.9714108 | LA6: 1.1837053 | LB6: 2.7361619 | LC6: 0.77390358 | LD6: 1.6422529 | LE6: 6.782709 | LF6: 1.6499582 | LG6: 0.47570183 | LH6: 0.65826 | LI6: 3.73014 | LJ6: 0.021186552 | LK6: 0.0070198591 | LL6: 0.010635306 | LM6: 0.042651813 | LN6: 100 | LO6: 0 | LP6: 100 | LQ6: 100 | LR6: 0.19659226 | LS6: 0.071287516 | LT6: 0.085747583 | LU6: 0.4211627 | LV6: 16.041978 | LW6: 5.7115391 | LX6: 1.3710747 | LY6: 33.786671 | LZ6: 6.4381702 | MA6: 1.4863512 | MB6: 2.6808645 | MC6: 15.191566 | MD6: 0.21113946 | ME6: 0.068892026 | MF6: 0.08749968 | MG6: 0.40986546 | MH6: 0.23329522 | MI6: 0.067337319 | MJ6: 0.095043617 | MK6: 0.40695636 | ML6: 0.44443468 | MM6: 0.11474728 | MN6: 0.226218 | MO6: 0.718351 | MP6: 0.28793808 | MQ6: 0.10481064 | MR6: 0.092946 | MS6: 0.55136767 | MT6: 0.44443468 | MU6: 0.11474728 | MV6: 0.226218 | MW6: 0.718351 | MX6: 0.090067276 | MY6: 0.02773364 | MZ6: 0.044393754 | NA6: 0.17443601 | NB6: 0.1106579 | NC6: 0.030848491 | ND6: 0.05575366 | NE6: 0.19639718 | NF6: -0.23600562 | NG6: 0.5381795 | NH6: -1.9174615 | NI6: 1.203091 | NJ6: 2.7277701 | NK6: 0.7764689 | NL6: 1.6410812 | NM6: 6.5669143 | NN6: 1.6578485 | NO6: 0.49526527 | NP6: 0.60996 | NQ6: 3.79086 | NR6: 0.020826317 | NS6: 0.0069120147 | NT6: 0.010650106 | NU6: 0.041773213 | NV6: 100 | NW6: 0 | NX6: 100 | NY6: 100 | NZ6: 0.1939691 | OA6: 0.07050904 | OB6: 0.087552259 | OC6: 0.41958906 | OD6: 16.136213 | OE6: 5.6702918 | OF6: 1.3931889 | OG6: 33.502875 | OH6: 6.4423039 | OI6: 1.579671 | OJ6: 2.6379239 | OK6: 16.394518 | OL6: 0.24641309 | OM6: -0.29068415 | ON6: 4.5588478 | OO6: 1.399099 | OP6: 1.810168 | OQ6: 3.209267 | OR6: 0.18622353 | OS6: 1.3178015e-05 | OT6: 0.0003057333 | OU6: 1.3178015e-05 | OV6: 0.00019983202 | OW6: 0.00027250698 | OX6: 3.3226317e-05 | OY6: 0.54712694 | OZ6: 0.26575057 | PA6: 0.33141718 | PB6: 10.964279 | PC6: 88.204901 | PD6: 0.23859958 | PE6: -0.16833683 | PF6: 3.6697694 | PG6: 1.158399 | PH6: 1.302677 | PI6: 2.461076 | PJ6: 0.18371274 | PK6: 1.2273466e-05 | PL6: 0.00030413737 | PM6: 1.2273466e-05 | PN6: 0.00020011414 | PO6: 0.00027268286 | PP6: 3.1454507e-05 | PQ6: 0.54757269 | PR6: 0.24890273 | PS6: 0.3010621 | PT6: 10.980087 | PU6: 88.201685 | PV6: 0.78728207 | PW6: 0.31585493 | PX6: 0.36297176 | PY6: 11.366869 | PZ6: 89.967128 | QA6: 0.78680698 | QB6: 0.29996775 | QC6: 0.3267789 | QD6: 11.382481 | QE6: 89.968612 | QF6: 1.5276159e-05 | QG6: 0.00028050378 | QH6: 0.00039273222 | QI6: 3.8465677e-05 | QJ6: 1.4366333e-05 | QK6: 0.0002804615 | QL6: 0.0003926155 | QM6: 3.6640381e-05 | QN6: 12.42692 | QO6: 92.023393 | QP6: 105.73571 | QQ6: 114.23774 | QR6: 11.879291 | QS6: 92.024449 | QT6: 101.98499 | QU6: 108.25339
A7: C45_5x5\C45_5x5\C45_B\C45_5x5 --- C45_B_x10_fusion_blue_5x5.mnt | B7: -1.0444332e-11 | C7: -6.2700624e-12 | D7: 1.1467706 | E7: 1.2040702 | F7: 1.6864795 | G7: 4.0570747 | H7: 4.2597907 | I7: 5.9664706 | J7: 27.119178 | K7: 28.265948 | L7: 28.265948 | M7: 28.265948 | N7: 27.061878 | O7: 28.265948 | P7: 26.579469 | Q7: 28.265948 | R7: 1.0643624 | S7: 0.15136154 | T7: 0.32890544 | U7: 1.368768 | V7: 0.98852415 | W7: 0.11937371 | X7: 0.52240312 | Y7: 1.2679904 | Z7: 2.0528866 | AA7: 0.2122915 | AB7: 0.900022 | AC7: 2.37538 | AD7: 0.57758719 | AE7: 0.054590565 | AF7: 0.42382744 | AG7: 0.69594362 | AH7: 2.0528866 | AI7: 0.2122915 | AJ7: 0.900022 | AK7: 2.37538 | AL7: 0.18691223 | AM7: 0.020033634 | AN7: 0.12525579 | AO7: 0.23972904 | AP7: 0.24022306 | AQ7: 0.024571987 | AR7: 0.15949362 | AS7: 0.30038195 | AT7: -0.11516724 | AU7: 0.18956534 | AV7: -0.43691854 | AW7: 0.56346745 | AX7: 3.8135555 | AY7: 0.42262776 | AZ7: 2.425136 | BA7: 5.2570117 | BB7: 0.03835356 | BC7: 0.05877305 | BD7: 0.022727033 | BE7: 0.57009333 | BF7: 4.1570975 | BG7: 0.69393871 | BH7: 0.21902848 | BI7: 5.166107 | BJ7: 41.330294 | BK7: 21.939859 | BL7: 4.1348404 | BM7: 100 | BN7: 0.38362741 | BO7: 0.04409377 | BP7: 0.28365093 | BQ7: 0.50743476 | BR7: 327.44459 | BS7: 61.173733 | BT7: 17.540987 | BU7: 440.00464 | BV7: 0.7195819 | BW7: 0.11119427 | BX7: 0.28265434 | BY7: 0.89904457 | BZ7: 0.73395643 | CA7: 0.096755115 | CB7: 0.38512366 | CC7: 1.0274534 | CD7: 1.4535383 | CE7: 0.091236423 | CF7: 0.667778 | CG7: 1.518264 | CH7: 0.53236462 | CI7: 0.048933362 | CJ7: 0.38141873 | CK7: 0.63231647 | CL7: 1.4535383 | CM7: 0.091236423 | CN7: 0.667778 | CO7: 1.518264 | CP7: 0.18226673 | CQ7: 0.020623353 | CR7: 0.091140335 | CS7: 0.22696861 | CT7: 0.22983873 | CU7: 0.024436102 | CV7: 0.11508894 | CW7: 0.2771431 | CX7: -0.12938462 | CY7: 0.21440345 | CZ7: -0.62448813 | DA7: 1.0351951 | DB7: 3.112223 | DC7: 0.29638034 | DD7: 2.2036427 | DE7: 4.0652836 | DF7: 0.036589449 | DG7: 0.06597844 | DH7: 0.021618397 | DI7: 0.73238571 | DJ7: 3.9827332 | DK7: 0.64537231 | DL7: 0.204804 | DM7: 4.7302735 | DN7: 86.302142 | DO7: 7.1686689 | DP7: 68.642194 | DQ7: 100 | DR7: 0.3806726 | DS7: 0.047295737 | DT7: 0.18854934 | DU7: 0.50072493 | DV7: 352.20382 | DW7: 63.979367 | DX7: 13.654008 | DY7: 462.56898 | DZ7: 0.73088149 | EA7: 0.12643182 | EB7: 0.12213616 | EC7: 0.98793008 | ED7: 0.75145317 | EE7: 0.11497589 | EF7: 0.24395484 | EG7: 0.99661182 | EH7: 1.4823347 | EI7: 0.21717063 | EJ7: 0.366091 | EK7: 1.8855063 | EL7: 0.5340481 | EM7: 0.062528411 | EN7: 0.28388723 | EO7: 0.67430528 | EP7: 1.9759948 | EQ7: 0.26568679 | ER7: 0.618788 | ES7: 2.493473 | ET7: 0.15821241 | EU7: 0.019841418 | EV7: 0.067644329 | EW7: 0.18895554 | EX7: 0.20698632 | EY7: 0.026424314 | EZ7: 0.087239994 | FA7: 0.2517953 | FB7: -0.18710015 | FC7: 0.22234242 | FD7: -0.66486123 | FE7: 0.54588699 | FF7: 4.2873805 | FG7: 0.48539263 | FH7: 3.0673966 | FI7: 7.7146033 | FJ7: 1.0141426 | FK7: 0.17970827 | FL7: 0.15233173 | FM7: 1.4270279 | FN7: 0.96185226 | FO7: 0.15688182 | FP7: 0.46645627 | FQ7: 1.3819834 | FR7: 1.8592091 | FS7: 0.26449927 | FT7: 0.618788 | FU7: 2.326661 | FV7: 1.5370097 | FW7: 0.3274671 | FX7: 0.327209 | FY7: 2.292421 | FZ7: 0.029152282 | GA7: 0.026289852 | GB7: 0.02017 | GC7: 0.32179875 | GD7: 4.0842118 | GE7: 0.69937412 | GF7: 0.18110879 | GG7: 5.1719756 | GH7: 48.40139 | GI7: 26.63983 | GJ7: 1.6498399 | GK7: 100 | GL7: 0.3153384 | GM7: 0.04070677 | GN7: 0.12463402 | GO7: 0.37738191 | GP7: 3.1090724 | GQ7: 1.056205 | GR7: 1.2804728 | GS7: 13.388601 | GT7: 384.81742 | GU7: 61.635264 | GV7: 31.075323 | GW7: 495.78582 | GX7: 0.59135679 | GY7: 0.10028933 | GZ7: 0.087017052 | HA7: 0.73195581 | HB7: 0.64668368 | HC7: 0.092300727 | HD7: 0.16067695 | HE7: 0.82525842 | HF7: 1.2380405 | HG7: 0.158772 | HH7: 0.247694 | HI7: 1.4533409 | HJ7: 0.49690394 | HK7: 0.05642435 | HL7: 0.2340036 | HM7: 0.60666738 | HN7: 1.5035613 | HO7: 0.14462166 | HP7: 0.613417 | HQ7: 1.787639 | HR7: 0.15454886 | HS7: 0.020735353 | HT7: 0.048454505 | HU7: 0.18256148 | HV7: 0.19810056 | HW7: 0.026291261 | HX7: 0.061918362 | HY7: 0.23425525 | HZ7: -0.22596489 | IA7: 0.18898468 | IB7: -0.6118432 | IC7: 0.24504368 | ID7: 3.5209402 | IE7: 0.35536743 | IF7: 2.8056446 | IG7: 6.4739344 | IH7: 0.72817792 | II7: 0.11976595 | IJ7: 0.15212005 | IK7: 0.99918334 | IL7: 0.77538335 | IM7: 0.10159094 | IN7: 0.46129695 | IO7: 1.0596845 | IP7: 1.4082382 | IQ7: 0.13205288 | IR7: 0.613417 | IS7: 1.67882 | IT7: 1.2776134 | IU7: 0.17174329 | IV7: 0.323794 | IW7: 1.536823 | IX7: 0.027815067 | IY7: 0.027910531 | IZ7: 0.019196276 | JA7: 0.343712 | JB7: 3.9225049 | JC7: 0.65796703 | JD7: 0.14899352 | JE7: 4.6718471 | JF7: 88.115922 | JG7: 8.5677184 | JH7: 52.327013 | JI7: 100 | JJ7: 0.31402341 | JK7: 0.044355988 | JL7: 0.086381908 | JM7: 0.37597491 | JN7: 5.0968334 | JO7: 1.2301949 | JP7: 3.1765575 | JQ7: 16.458887 | JR7: 407.92337 | JS7: 64.702396 | JT7: 29.094125 | JU7: 520.93438 | JV7: 0.20028927 | JW7: 0.046206364 | JX7: 0.084182547 | JY7: 0.34583562 | JZ7: 0.21564286 | KA7: 0.095343896 | KB7: 0.082391322 | KC7: 0.61447207 | KD7: 0.41593213 | KE7: 0.11819229 | KF7: 0.166603 | KG7: 0.857506 | KH7: 0.25431297 | KI7: 0.063827527 | KJ7: 0.10746567 | KK7: 0.4452 | KL7: 0.41593213 | KM7: 0.11819229 | KN7: 0.166603 | KO7: 0.857506 | KP7: 0.082863916 | KQ7: 0.019711633 | KR7: 0.042567161 | KS7: 0.14231957 | KT7: 0.10283512 | KU7: 0.025227026 | KV7: 0.050090165 | KW7: 0.17601946 | KX7: -0.098979728 | KY7: 0.54460297 | KZ7: -2.1550201 | LA7: 1.1865123 | LB7: 2.7141912 | LC7: 0.9475052 | LD7: 1.6299395 | LE7: 8.6443289 | LF7: 1.8057908 | LG7: 0.5090753 | LH7: 1.0833 | LI7: 4.27248 | LJ7: 0.01877553 | LK7: 0.0044098347 | LL7: 0.0096096976 | LM7: 0.029394146 | LN7: 100 | LO7: 0 | LP7: 100 | LQ7: 100 | LR7: 0.17724724 | LS7: 0.043997927 | LT7: 0.099705757 | LU7: 0.32134261 | LV7: 16.218534 | LW7: 5.3174793 | LX7: 0 | LY7: 29.661286 | LZ7: 5.8770397 | MA7: 1.2782122 | MB7: 2.340561 | MC7: 9.2310533 | MD7: 0.19520931 | ME7: 0.045221468 | MF7: 0.079768883 | MG7: 0.32268028 | MH7: 0.20311694 | MI7: 0.076480453 | MJ7: 0.078165729 | MK7: 0.48518661 | ML7: 0.39832625 | MM7: 0.10003654 | MN7: 0.165577 | MO7: 0.693964 | MP7: 0.24654955 | MQ7: 0.062719533 | MR7: 0.115028 | MS7: 0.411719 | MT7: 0.39832625 | MU7: 0.10003654 | MV7: 0.165577 | MW7: 0.693964 | MX7: 0.080235295 | MY7: 0.01742881 | MZ7: 0.040827117 | NA7: 0.1234839 | NB7: 0.099237671 | NC7: 0.021821869 | ND7: 0.047906453 | NE7: 0.15533647 | NF7: -0.07213646 | NG7: 0.50647572 | NH7: -1.8081789 | NI7: 1.190787 | NJ7: 2.6451271 | NK7: 0.76683939 | NL7: 1.5650625 | NM7: 6.8852579 | NN7: 1.7899113 | NO7: 0.50215198 | NP7: 1.08744 | NQ7: 4.71408 | NR7: 0.018224783 | NS7: 0.0042179413 | NT7: 0.0090381306 | NU7: 0.028483129 | NV7: 100 | NW7: 0 | NX7: 100 | NY7: 100 | NZ7: 0.17235216 | OA7: 0.040621811 | OB7: 0.098197373 | OC7: 0.29719527 | OD7: 16.484085 | OE7: 5.165341 | OF7: 0 | OG7: 29.544449 | OH7: 5.9136152 | OI7: 1.2576669 | OJ7: 2.1213047 | OK7: 9.1959097 | OL7: 0.21492077 | OM7: -0.17070955 | ON7: 4.5086553 | OO7: 1.470893 | OP7: 1.371746 | OQ7: 2.842639 | OR7: 0.1634329 | OS7: 1.1722036e-05 | OT7: 0.00026163965 | OU7: 1.1722036e-05 | OV7: 0.00017792597 | OW7: 0.00023319303 | OX7: 2.8446619e-05 | OY7: 0.48929127 | OZ7: 0.23483177 | PA7: 0.27647615 | PB7: 9.827833 | PC7: 88.062581 | PD7: 0.20539429 | PE7: -0.20165773 | PF7: 3.4887759 | PG7: 1.050761 | PH7: 1.121247 | PI7: 2.172008 | PJ7: 0.15988878 | PK7: 1.0094464e-05 | PL7: 0.00025886572 | PM7: 1.0094464e-05 | PN7: 0.00017700163 | PO7: 0.00023199237 | PP7: 2.6873345e-05 | PQ7: 0.49054888 | PR7: 0.20150975 | PS7: 0.25117421 | PT7: 9.6689821 | PU7: 88.246165 | PV7: 0.67956848 | PW7: 0.28153718 | PX7: 0.28744335 | PY7: 10.015177 | PZ7: 89.602425 | QA7: 0.67984673 | QB7: 0.24583377 | QC7: 0.26007017 | QD7: 9.9701111 | QE7: 90.211436 | QF7: 1.4072539e-05 | QG7: 0.00024123985 | QH7: 0.00032377715 | QI7: 3.1940423e-05 | QJ7: 1.2304394e-05 | QK7: 0.00023958343 | QL7: 0.00032271557 | QM7: 2.9682891e-05 | QN7: 39.475229 | QO7: 89.986735 | QP7: 104.77443 | QQ7: 120.74063 | QR7: 37.433252 | QS7: 89.986621 | QT7: 104.77424 | QU7: 120.73948
