Workbook

Sheet Baza
A1: # | B1: OPERATOR:2 | C1: OPERATOR:2 | D1: OPERATOR:4 | E1: OPERATOR:8 | F1: OPERATOR:9 | G1: OPERATOR:5 | H1: OPERATOR:10 | I1: OPERATOR:11 | J1: 5 | K1: 5 | L1: 6 | M1: 6 | N1: 13 | O1: 13 | P1: 14 | Q1: 14 | R1: 40 | S1: 40 | T1: 40 | U1: 40 | V1: 40 | W1: 40 | X1: 40 | Y1: 40 | Z1: 40 | AA1: 40 | AB1: 40 | AC1: 40 | AD1: 40 | AE1: 40 | AF1: 40 | AG1: 40 | AH1: 40 | AI1: 40 | AJ1: 40 | AK1: 40 | AL1: 40 | AM1: 40 | AN1: 40 | AO1: 40 | AP1: 40 | AQ1: 40 | AR1: 40 | AS1: 40 | AT1: 40 | AU1: 40 | AV1: 40 | AW1: 40 | AX1: 40 | AY1: 40 | AZ1: 40 | BA1: 40 | BB1: 40 | BC1: 40 | BD1: 40 | BE1: 40 | BF1: 40 | BG1: 40 | BH1: 40 | BI1: 40 | BJ1: 40 | BK1: 40 | BL1: 40 | BM1: 40 | BN1: 40 | BO1: 40 | BP1: 40 | BQ1: 40 | BR1: 40 | BS1: 40 | BT1: 40 | BU1: 40 | BV1: 41 | BW1: 41 | BX1: 41 | BY1: 41 | BZ1: 41 | CA1: 41 | CB1: 41 | CC1: 41 | CD1: 41 | CE1: 41 | CF1: 41 | CG1: 41 | CH1: 41 | CI1: 41 | CJ1: 41 | CK1: 41 | CL1: 41 | CM1: 41 | CN1: 41 | CO1: 41 | CP1: 41 | CQ1: 41 | CR1: 41 | CS1: 41 | CT1: 41 | CU1: 41 | CV1: 41 | CW1: 41 | CX1: 41 | CY1: 41 | CZ1: 41 | DA1: 41 | DB1: 41 | DC1: 41 | DD1: 41 | DE1: 41 | DF1: 41 | DG1: 41 | DH1: 41 | DI1: 41 | DJ1: 41 | DK1: 41 | DL1: 41 | DM1: 41 | DN1: 41 | DO1: 41 | DP1: 41 | DQ1: 41 | DR1: 41 | DS1: 41 | DT1: 41 | DU1: 41 | DV1: 41 | DW1: 41 | DX1: 41 | DY1: 41 | DZ1: 50 | EA1: 50 | EB1: 50 | EC1: 50 | ED1: 50 | EE1: 50 | EF1: 50 | EG1: 50 | EH1: 50 | EI1: 50 | EJ1: 50 | EK1: 50 | EL1: 50 | EM1: 50 | EN1: 50 | EO1: 50 | EP1: 50 | EQ1: 50 | ER1: 50 | ES1: 50 | ET1: 50 | EU1: 50 | EV1: 50 | EW1: 50 | EX1: 50 | EY1: 50 | EZ1: 50 | FA1: 50 | FB1: 50 | FC1: 50 | FD1: 50 | FE1: 50 | FF1: 50 | FG1: 50 | FH1: 50 | FI1: 50 | FJ1: 50 | FK1: 50 | FL1: 50 | FM1: 50 | FN1: 50 | FO1: 50 | FP1: 50 | FQ1: 50 | FR1: 50 | FS1: 50 | FT1: 50 | FU1: 50 | FV1: 50 | FW1: 50 | FX1: 50 | FY1: 50 | FZ1: 50 | GA1: 50 | GB1: 50 | GC1: 50 | GD1: 50 | GE1: 50 | GF1: 50 | GG1: 50 | GH1: 50 | GI1: 50 | GJ1: 50 | GK1: 50 | GL1: 50 | GM1: 50 | GN1: 50 | GO1: 50 | GP1: 50 | GQ1: 50 | GR1: 50 | GS1: 50 | GT1: 50 | GU1: 50 | GV1: 50 | GW1: 50 | GX1: 51 | GY1: 51 | GZ1: 51 | HA1: 51 | HB1: 51 | HC1: 51 | HD1: 51 | HE1: 51 | HF1: 51 | HG1: 51 | HH1: 51 | HI1: 51 | HJ1: 51 | HK1: 51 | HL1: 51 | HM1: 51 | HN1: 51 | HO1: 51 | HP1: 51 | HQ1: 51 | HR1: 51 | HS1: 51 | HT1: 51 | HU1: 51 | HV1: 51 | HW1: 51 | HX1: 51 | HY1: 51 | HZ1: 51 | IA1: 51 | IB1: 51 | IC1: 51 | ID1: 51 | IE1: 51 | IF1: 51 | IG1: 51 | IH1: 51 | II1: 51 | IJ1: 51 | IK1: 51 | IL1: 51 | IM1: 51 | IN1: 51 | IO1: 51 | IP1: 51 | IQ1: 51 | IR1: 51 | IS1: 51 | IT1: 51 | IU1: 51 | IV1: 51 | IW1: 51 | IX1: 51 | IY1: 51 | IZ1: 51 | JA1: 51 | JB1: 51 | JC1: 51 | JD1: 51 | JE1: 51 | JF1: 51 | JG1: 51 | JH1: 51 | JI1: 51 | JJ1: 51 | JK1: 51 | JL1: 51 | JM1: 51 | JN1: 51 | JO1: 51 | JP1: 51 | JQ1: 51 | JR1: 51 | JS1: 51 | JT1: 51 | JU1: 51 | JV1: 60 | JW1: 60 | JX1: 60 | JY1: 60 | JZ1: 60 | KA1: 60 | KB1: 60 | KC1: 60 | KD1: 60 | KE1: 60 | KF1: 60 | KG1: 60 | KH1: 60 | KI1: 60 | KJ1: 60 | KK1: 60 | KL1: 60 | KM1: 60 | KN1: 60 | KO1: 60 | KP1: 60 | KQ1: 60 | KR1: 60 | KS1: 60 | KT1: 60 | KU1: 60 | KV1: 60 | KW1: 60 | KX1: 60 | KY1: 60 | KZ1: 60 | LA1: 60 | LB1: 60 | LC1: 60 | LD1: 60 | LE1: 60 | LF1: 60 | LG1: 60 | LH1: 60 | LI1: 60 | LJ1: 60 | LK1: 60 | LL1: 60 | LM1: 60 | LN1: 60 | LO1: 60 | LP1: 60 | LQ1: 60 | LR1: 60 | LS1: 60 | LT1: 60 | LU1: 60 | LV1: 60 | LW1: 60 | LX1: 60 | LY1: 60 | LZ1: 60 | MA1: 60 | MB1: 60 | MC1: 60 | MD1: 61 | ME1: 61 | MF1: 61 | MG1: 61 | MH1: 61 | MI1: 61 | MJ1: 61 | MK1: 61 | ML1: 61 | MM1: 61 | MN1: 61 | MO1: 61 | MP1: 61 | MQ1: 61 | MR1: 61 | MS1: 61 | MT1: 61 | MU1: 61 | MV1: 61 | MW1: 61 | MX1: 61 | MY1: 61 | MZ1: 61 | NA1: 61 | NB1: 61 | NC1: 61 | ND1: 61 | NE1: 61 | NF1: 61 | NG1: 61 | NH1: 61 | NI1: 61 | NJ1: 61 | NK1: 61 | NL1: 61 | NM1: 61 | NN1: 61 | NO1: 61 | NP1: 61 | NQ1: 61 | NR1: 61 | NS1: 61 | NT1: 61 | NU1: 61 | NV1: 61 | NW1: 61 | NX1: 61 | NY1: 61 | NZ1: 61 | OA1: 61 | OB1: 61 | OC1: 61 | OD1: 61 | OE1: 61 | OF1: 61 | OG1: 61 | OH1: 61 | OI1: 61 | OJ1: 61 | OK1: 61 | OL1: 70 | OM1: 70 | ON1: 70 | OO1: 70 | OP1: 70 | OQ1: 70 | OR1: 70 | OS1: 70 | OT1: 70 | OU1: 70 | OV1: 70 | OW1: 70 | OX1: 70 | OY1: 70 | OZ1: 70 | PA1: 70 | PB1: 70 | PC1: 70 | PD1: 71 | PE1: 71 | PF1: 71 | PG1: 71 | PH1: 71 | PI1: 71 | PJ1: 71 | PK1: 71 | PL1: 71 | PM1: 71 | PN1: 71 | PO1: 71 | PP1: 71 | PQ1: 71 | PR1: 71 | PS1: 71 | PT1: 71 | PU1: 71 | PV1: 80 | PW1: 80 | PX1: 80 | PY1: 80 | PZ1: 80 | QA1: 81 | QB1: 81 | QC1: 81 | QD1: 81 | QE1: 81 | QF1: 90 | QG1: 90 | QH1: 90 | QI1: 90 | QJ1: 91 | QK1: 91 | QL1: 91 | QM1: 91 | QN1: 92 | QO1: 92 | QP1: 92 | QQ1: 92 | QR1: 93 | QS1: 93 | QT1: 93 | QU1: 93
A2: # | B2: Kąt obrotu osi X | C2: Kąt obrotu osi Y | D2: Area_NM (Amp_full-Amp_NM) | E2: Area NM_005 (Aev_005-Amp_005) | F2: Area NM_05 (Aev_05-Amp_05) | G2: Procent_NM (((Area_NM/Aev)*100)) | H2: Procent NM_005 (((Area_NM_005/Aev)*100)) | I2: Procent NM_05 (((Area_NM_05/Aev)*100)) | J2: Amp | K2: Aev | L2: Amp | M2: Aev | N2: Amp | O2: Aev | P2: Amp | Q2: Aev | R2: Pp[Średnia] | S2: Pp[Std odch] | T2: Pp[Min] | U2: Pp[Max] | V2: Pv[Średnia] | W2: Pv[Std odch] | X2: Pv[Min] | Y2: Pv[Max] | Z2: Pz[Średnia] | AA2: Pz[Std odch] | AB2: Pz[Min] | AC2: Pz[Max] | AD2: Pc (Brak uśredniania (pojedyncza wartość))[Średnia] | AE2: Pc (Brak uśredniania (pojedyncza wartość))[Std odch] | AF2: Pc (Brak uśredniania (pojedyncza wartość))[Min] | AG2: Pc (Brak uśredniania (pojedyncza wartość))[Max] | AH2: Pt[Średnia] | AI2: Pt[Std odch] | AJ2: Pt[Min] | AK2: Pt[Max] | AL2: Pa[Średnia] | AM2: Pa[Std odch] | AN2: Pa[Min] | AO2: Pa[Max] | AP2: Pq[Średnia] | AQ2: Pq[Std odch] | AR2: Pq[Min] | AS2: Pq[Max] | AT2: Psk[Średnia] | AU2: Psk[Std odch] | AV2: Psk[Min] | AW2: Psk[Max] | AX2: Pku[Średnia] | AY2: Pku[Std odch] | AZ2: Pku[Min] | BA2: Pku[Max] | BB2: PSm (Brak uśredniania (pojedyncza wartość))[Średnia] | BC2: PSm (Brak uśredniania (pojedyncza wartość))[Std odch] | BD2: PSm (Brak uśredniania (pojedyncza wartość))[Min] | BE2: PSm (Brak uśredniania (pojedyncza wartość))[Max] | BF2: Pdq[Średnia] | BG2: Pdq[Std odch] | BH2: Pdq[Min] | BI2: Pdq[Max] | BJ2: Pmr (c = 1 µm poniżej najwyższego wypiętrzenia)[Średnia] | BK2: Pmr (c = 1 µm poniżej najwyższego wypiętrzenia)[Std odch] | BL2: Pmr (c = 1 µm poniżej najwyższego wypiętrzenia)[Min] | BM2: Pmr (c = 1 µm poniżej najwyższego wypiętrzenia)[Max] | BN2: Pdc (p = 20%, q = 80%)[Średnia] | BO2: Pdc (p = 20%, q = 80%)[Std odch] | BP2: Pdc (p = 20%, q = 80%)[Min] | BQ2: Pdc (p = 20%, q = 80%)[Max] | BR2: PPc (Brak uśredniania (pojedyncza wartość))[Średnia] | BS2: PPc (Brak uśredniania (pojedyncza wartość))[Std odch] | BT2: PPc (Brak uśredniania (pojedyncza wartość))[Min] | BU2: PPc (Brak uśredniania (pojedyncza wartość))[Max] | BV2: Pp[Średnia] | BW2: Pp[Std odch] | BX2: Pp[Min] | BY2: Pp[Max] | BZ2: Pv[Średnia] | CA2: Pv[Std odch] | CB2: Pv[Min] | CC2: Pv[Max] | CD2: Pz[Średnia] | CE2: Pz[Std odch] | CF2: Pz[Min] | CG2: Pz[Max] | CH2: Pc (Brak uśredniania (pojedyncza wartość))[Średnia] | CI2: Pc (Brak uśredniania (pojedyncza wartość))[Std odch] | CJ2: Pc (Brak uśredniania (pojedyncza wartość))[Min] | CK2: Pc (Brak uśredniania (pojedyncza wartość))[Max] | CL2: Pt[Średnia] | CM2: Pt[Std odch] | CN2: Pt[Min] | CO2: Pt[Max] | CP2: Pa[Średnia] | CQ2: Pa[Std odch] | CR2: Pa[Min] | CS2: Pa[Max] | CT2: Pq[Średnia] | CU2: Pq[Std odch] | CV2: Pq[Min] | CW2: Pq[Max] | CX2: Psk[Średnia] | CY2: Psk[Std odch] | CZ2: Psk[Min] | DA2: Psk[Max] | DB2: Pku[Średnia] | DC2: Pku[Std odch] | DD2: Pku[Min] | DE2: Pku[Max] | DF2: PSm (Brak uśredniania (pojedyncza wartość))[Średnia] | DG2: PSm (Brak uśredniania (pojedyncza wartość))[Std odch] | DH2: PSm (Brak uśredniania (pojedyncza wartość))[Min] | DI2: PSm (Brak uśredniania (pojedyncza wartość))[Max] | DJ2: Pdq[Średnia] | DK2: Pdq[Std odch] | DL2: Pdq[Min] | DM2: Pdq[Max] | DN2: Pmr (c = 1 µm poniżej najwyższego wypiętrzenia)[Średnia] | DO2: Pmr (c = 1 µm poniżej najwyższego wypiętrzenia)[Std odch] | DP2: Pmr (c = 1 µm poniżej najwyższego wypiętrzenia)[Min] | DQ2: Pmr (c = 1 µm poniżej najwyższego wypiętrzenia)[Max] | DR2: Pdc (p = 20%, q = 80%)[Średnia] | DS2: Pdc (p = 20%, q = 80%)[Std odch] | DT2: Pdc (p = 20%, q = 80%)[Min] | DU2: Pdc (p = 20%, q = 80%)[Max] | DV2: PPc (Brak uśredniania (pojedyncza wartość))[Średnia] | DW2: PPc (Brak uśredniania (pojedyncza wartość))[Std odch] | DX2: PPc (Brak uśredniania (pojedyncza wartość))[Min] | DY2: PPc (Brak uśredniania (pojedyncza wartość))[Max] | DZ2: Rp[Średnia] | EA2: Rp[Std odch] | EB2: Rp[Min] | EC2: Rp[Max] | ED2: Rv[Średnia] | EE2: Rv[Std odch] | EF2: Rv[Min] | EG2: Rv[Max] | EH2: Rz[Średnia] | EI2: Rz[Std odch] | EJ2: Rz[Min] | EK2: Rz[Max] | EL2: Rc (Brak uśredniania (pojedyncza wartość))[Średnia] | EM2: Rc (Brak uśredniania (pojedyncza wartość))[Std odch] | EN2: Rc (Brak uśredniania (pojedyncza wartość))[Min] | EO2: Rc (Brak uśredniania (pojedyncza wartość))[Max] | EP2: Rt[Średnia] | EQ2: Rt[Std odch] | ER2: Rt[Min] | ES2: Rt[Max] | ET2: Ra[Średnia] | EU2: Ra[Std odch] | EV2: Ra[Min] | EW2: Ra[Max] | EX2: Rq[Średnia] | EY2: Rq[Std odch] | EZ2: Rq[Min] | FA2: Rq[Max] | FB2: Rsk[Średnia] | FC2: Rsk[Std odch] | FD2: Rsk[Min] | FE2: Rsk[Max] | FF2: Rku[Średnia] | FG2: Rku[Std odch] | FH2: Rku[Min] | FI2: Rku[Max] | FJ2: Rp1max[Średnia] | FK2: Rp1max[Std odch] | FL2: Rp1max[Min] | FM2: Rp1max[Max] | FN2: Rv1max[Średnia] | FO2: Rv1max[Std odch] | FP2: Rv1max[Min] | FQ2: Rv1max[Max] | FR2: Rz1max[Średnia] | FS2: Rz1max[Std odch] | FT2: Rz1max[Min] | FU2: Rz1max[Max] | FV2: Rz(n) (Wskaźnik λc = 1)[Średnia] | FW2: Rz(n) (Wskaźnik λc = 1)[Std odch] | FX2: Rz(n) (Wskaźnik λc = 1)[Min] | FY2: Rz(n) (Wskaźnik λc = 1)[Max] | FZ2: RSm (Brak uśredniania (pojedyncza wartość))[Średnia] | GA2: RSm (Brak uśredniania (pojedyncza wartość))[Std odch] | GB2: RSm (Brak uśredniania (pojedyncza wartość))[Min] | GC2: RSm (Brak uśredniania (pojedyncza wartość))[Max] | GD2: Rdq[Średnia] | GE2: Rdq[Std odch] | GF2: Rdq[Min] | GG2: Rdq[Max] | GH2: Rmr (c = 1 µm poniżej najwyższego wypiętrzenia)[Średnia] | GI2: Rmr (c = 1 µm poniżej najwyższego wypiętrzenia)[Std odch] | GJ2: Rmr (c = 1 µm poniżej najwyższego wypiętrzenia)[Min] | GK2: Rmr (c = 1 µm poniżej najwyższego wypiętrzenia)[Max] | GL2: Rdc (p = 20%, q = 80%)[Średnia] | GM2: Rdc (p = 20%, q = 80%)[Std odch] | GN2: Rdc (p = 20%, q = 80%)[Min] | GO2: Rdc (p = 20%, q = 80%)[Max] | GP2: Rmr (Rz/4) (c = Rz/4 µm powyżej płaszczyzny średniej)[Średnia] | GQ2: Rmr (Rz/4) (c = Rz/4 µm powyżej płaszczyzny średniej)[Std odch] | GR2: Rmr (Rz/4) (c = Rz/4 µm powyżej płaszczyzny średniej)[Min] | GS2: Rmr (Rz/4) (c = Rz/4 µm powyżej płaszczyzny średniej)[Max] | GT2: RPc (Brak uśredniania (pojedyncza wartość))[Średnia] | GU2: RPc (Brak uśredniania (pojedyncza wartość))[Std odch] | GV2: RPc (Brak uśredniania (pojedyncza wartość))[Min] | GW2: RPc (Brak uśredniania (pojedyncza wartość))[Max] | GX2: Rp[Średnia] | GY2: Rp[Std odch] | GZ2: Rp[Min] | HA2: Rp[Max] | HB2: Rv[Średnia] | HC2: Rv[Std odch] | HD2: Rv[Min] | HE2: Rv[Max] | HF2: Rz[Średnia] | HG2: Rz[Std odch] | HH2: Rz[Min] | HI2: Rz[Max] | HJ2: Rc (Brak uśredniania (pojedyncza wartość))[Średnia] | HK2: Rc (Brak uśredniania (pojedyncza wartość))[Std odch] | HL2: Rc (Brak uśredniania (pojedyncza wartość))[Min] | HM2: Rc (Brak uśredniania (pojedyncza wartość))[Max] | HN2: Rt[Średnia] | HO2: Rt[Std odch] | HP2: Rt[Min] | HQ2: Rt[Max] | HR2: Ra[Średnia] | HS2: Ra[Std odch] | HT2: Ra[Min] | HU2: Ra[Max] | HV2: Rq[Średnia] | HW2: Rq[Std odch] | HX2: Rq[Min] | HY2: Rq[Max] | HZ2: Rsk[Średnia] | IA2: Rsk[Std odch] | IB2: Rsk[Min] | IC2: Rsk[Max] | ID2: Rku[Średnia] | IE2: Rku[Std odch] | IF2: Rku[Min] | IG2: Rku[Max] | IH2: Rp1max[Średnia] | II2: Rp1max[Std odch] | IJ2: Rp1max[Min] | IK2: Rp1max[Max] | IL2: Rv1max[Średnia] | IM2: Rv1max[Std odch] | IN2: Rv1max[Min] | IO2: Rv1max[Max] | IP2: Rz1max[Średnia] | IQ2: Rz1max[Std odch] | IR2: Rz1max[Min] | IS2: Rz1max[Max] | IT2: Rz(n) (Wskaźnik λc = 1)[Średnia] | IU2: Rz(n) (Wskaźnik λc = 1)[Std odch] | IV2: Rz(n) (Wskaźnik λc = 1)[Min] | IW2: Rz(n) (Wskaźnik λc = 1)[Max] | IX2: RSm (Brak uśredniania (pojedyncza wartość))[Średnia] | IY2: RSm (Brak uśredniania (pojedyncza wartość))[Std odch] | IZ2: RSm (Brak uśredniania (pojedyncza wartość))[Min] | JA2: RSm (Brak uśredniania (pojedyncza wartość))[Max] | JB2: Rdq[Średnia] | JC2: Rdq[Std odch] | JD2: Rdq[Min] | JE2: Rdq[Max] | JF2: Rmr (c = 1 µm poniżej najwyższego wypiętrzenia)[Średnia] | JG2: Rmr (c = 1 µm poniżej najwyższego wypiętrzenia)[Std odch] | JH2: Rmr (c = 1 µm poniżej najwyższego wypiętrzenia)[Min] | JI2: Rmr (c = 1 µm poniżej najwyższego wypiętrzenia)[Max] | JJ2: Rdc (p = 20%, q = 80%)[Średnia] | JK2: Rdc (p = 20%, q = 80%)[Std odch] | JL2: Rdc (p = 20%, q = 80%)[Min] | JM2: Rdc (p = 20%, q = 80%)[Max] | JN2: Rmr (Rz/4) (c = Rz/4 µm powyżej płaszczyzny średniej)[Średnia] | JO2: Rmr (Rz/4) (c = Rz/4 µm powyżej płaszczyzny średniej)[Std odch] | JP2: Rmr (Rz/4) (c = Rz/4 µm powyżej płaszczyzny średniej)[Min] | JQ2: Rmr (Rz/4) (c = Rz/4 µm powyżej płaszczyzny średniej)[Max] | JR2: RPc (Brak uśredniania (pojedyncza wartość))[Średnia] | JS2: RPc (Brak uśredniania (pojedyncza wartość))[Std odch] | JT2: RPc (Brak uśredniania (pojedyncza wartość))[Min] | JU2: RPc (Brak uśredniania (pojedyncza wartość))[Max] | JV2: Wp[Średnia] | JW2: Wp[Std odch] | JX2: Wp[Min] | JY2: Wp[Max] | JZ2: Wv[Średnia] | KA2: Wv[Std odch] | KB2: Wv[Min] | KC2: Wv[Max] | KD2: Wz[Średnia] | KE2: Wz[Std odch] | KF2: Wz[Min] | KG2: Wz[Max] | KH2: Wc[Średnia] | KI2: Wc[Std odch] | KJ2: Wc[Min] | KK2: Wc[Max] | KL2: Wt[Średnia] | KM2: Wt[Std odch] | KN2: Wt[Min] | KO2: Wt[Max] | KP2: Wa[Średnia] | KQ2: Wa[Std odch] | KR2: Wa[Min] | KS2: Wa[Max] | KT2: Wq[Średnia] | KU2: Wq[Std odch] | KV2: Wq[Min] | KW2: Wq[Max] | KX2: Wsk[Średnia] | KY2: Wsk[Std odch] | KZ2: Wsk[Min] | LA2: Wsk[Max] | LB2: Wku[Średnia] | LC2: Wku[Std odch] | LD2: Wku[Min] | LE2: Wku[Max] | LF2: WSm[Średnia] | LG2: WSm[Std odch] | LH2: WSm[Min] | LI2: WSm[Max] | LJ2: Wdq[Średnia] | LK2: Wdq[Std odch] | LL2: Wdq[Min] | LM2: Wdq[Max] | LN2: Wmr (c = 1 µm poniżej najwyższego wypiętrzenia)[Średnia] | LO2: Wmr (c = 1 µm poniżej najwyższego wypiętrzenia)[Std odch] | LP2: Wmr (c = 1 µm poniżej najwyższego wypiętrzenia)[Min] | LQ2: Wmr (c = 1 µm poniżej najwyższego wypiętrzenia)[Max] | LR2: Wdc (p = 20%, q = 80%)[Średnia] | LS2: Wdc (p = 20%, q = 80%)[Std odch] | LT2: Wdc (p = 20%, q = 80%)[Min] | LU2: Wdc (p = 20%, q = 80%)[Max] | LV2: Wmr (Wz/4)[Średnia] | LW2: Wmr (Wz/4)[Std odch] | LX2: Wmr (Wz/4)[Min] | LY2: Wmr (Wz/4)[Max] | LZ2: WPc[Średnia] | MA2: WPc[Std odch] | MB2: WPc[Min] | MC2: WPc[Max] | MD2: Wp[Średnia] | ME2: Wp[Std odch] | MF2: Wp[Min] | MG2: Wp[Max] | MH2: Wv[Średnia] | MI2: Wv[Std odch] | MJ2: Wv[Min] | MK2: Wv[Max] | ML2: Wz[Średnia] | MM2: Wz[Std odch] | MN2: Wz[Min] | MO2: Wz[Max] | MP2: Wc[Średnia] | MQ2: Wc[Std odch] | MR2: Wc[Min] | MS2: Wc[Max] | MT2: Wt[Średnia] | MU2: Wt[Std odch] | MV2: Wt[Min] | MW2: Wt[Max] | MX2: Wa[Średnia] | MY2: Wa[Std odch] | MZ2: Wa[Min] | NA2: Wa[Max] | NB2: Wq[Średnia] | NC2: Wq[Std odch] | ND2: Wq[Min] | NE2: Wq[Max] | NF2: Wsk[Średnia] | NG2: Wsk[Std odch] | NH2: Wsk[Min] | NI2: Wsk[Max] | NJ2: Wku[Średnia] | NK2: Wku[Std odch] | NL2: Wku[Min] | NM2: Wku[Max] | NN2: WSm[Średnia] | NO2: WSm[Std odch] | NP2: WSm[Min] | NQ2: WSm[Max] | NR2: Wdq[Średnia] | NS2: Wdq[Std odch] | NT2: Wdq[Min] | NU2: Wdq[Max] | NV2: Wmr (c = 1 µm poniżej najwyższego wypiętrzenia)[Średnia] | NW2: Wmr (c = 1 µm poniżej najwyższego wypiętrzenia)[Std odch] | NX2: Wmr (c = 1 µm poniżej najwyższego wypiętrzenia)[Min] | NY2: Wmr (c = 1 µm poniżej najwyższego wypiętrzenia)[Max] | NZ2: Wdc (p = 20%, q = 80%)[Średnia] | OA2: Wdc (p = 20%, q = 80%)[Std odch] | OB2: Wdc (p = 20%, q = 80%)[Min] | OC2: Wdc (p = 20%, q = 80%)[Max] | OD2: Wmr (Wz/4)[Średnia] | OE2: Wmr (Wz/4)[Std odch] | OF2: Wmr (Wz/4)[Min] | OG2: Wmr (Wz/4)[Max] | OH2: WPc[Średnia] | OI2: WPc[Std odch] | OJ2: WPc[Min] | OK2: WPc[Max] | OL2: Sq | OM2: Ssk | ON2: Sku | OO2: Sp | OP2: Sv | OQ2: Sz | OR2: Sa | OS2: Vm (p = 10%) | OT2: Vv (p = 10%) | OU2: Vmp (p = 10%) | OV2: Vmc (p = 10%, q = 80%) | OW2: Vvc (p = 10%, q = 80%) | OX2: Vvv (p = 80%) | OY2: Sk | OZ2: Spk | PA2: Svk | PB2: Smrk1 | PC2: Smrk2 | PD2: Sq | PE2: Ssk | PF2: Sku | PG2: Sp | PH2: Sv | PI2: Sz | PJ2: Sa | PK2: Vm (p = 10%) | PL2: Vv (p = 10%) | PM2: Vmp (p = 10%) | PN2: Vmc (p = 10%, q = 80%) | PO2: Vvc (p = 10%, q = 80%) | PP2: Vvv (p = 80%) | PQ2: Sk | PR2: Spk | PS2: Svk | PT2: Smrk1 | PU2: Smrk2 | PV2: Sk | PW2: Spk | PX2: Svk | PY2: Smrk1 | PZ2: Smrk2 | QA2: Sk | QB2: Spk | QC2: Svk | QD2: Smrk1 | QE2: Smrk2 | QF2: Vmp | QG2: Vmc | QH2: Vvc | QI2: Vvv | QJ2: Vmp | QK2: Vmc | QL2: Vvc | QM2: Vvv | QN2: Izotropię | QO2: Pierwszy kierunek | QP2: Drugi kierunek | QQ2: Trzeci kierunek | QR2: Izotropię | QS2: Pierwszy kierunek | QT2: Drugi kierunek | QU2: Trzeci kierunek
A3: # | B3: ° | C3: ° | D3: mm² | E3: mm2 | F3: mm2 | G3: % | H3: % | I3: % | J3: mm² | K3: mm² | L3: mm² | M3: mm² | N3: mm² | O3: mm² | P3: mm² | Q3: mm² | R3: µm | S3: µm | T3: µm | U3: µm | V3: µm | W3: µm | X3: µm | Y3: µm | Z3: µm | AA3: µm | AB3: µm | AC3: µm | AD3: µm | AE3: µm | AF3: µm | AG3: µm | AH3: µm | AI3: µm | AJ3: µm | AK3: µm | AL3: µm | AM3: µm | AN3: µm | AO3: µm | AP3: µm | AQ3: µm | AR3: µm | AS3: µm | AT3: <no unit> | AU3: <no unit> | AV3: <no unit> | AW3: <no unit> | AX3: <no unit> | AY3: <no unit> | AZ3: <no unit> | BA3: <no unit> | BB3: mm | BC3: mm | BD3: mm | BE3: mm | BF3: ° | BG3: ° | BH3: ° | BI3: ° | BJ3: % | BK3: % | BL3: % | BM3: % | BN3: µm | BO3: µm | BP3: µm | BQ3: µm | BR3: 1/cm | BS3: 1/cm | BT3: 1/cm | BU3: 1/cm | BV3: µm | BW3: µm | BX3: µm | BY3: µm | BZ3: µm | CA3: µm | CB3: µm | CC3: µm | CD3: µm | CE3: µm | CF3: µm | CG3: µm | CH3: µm | CI3: µm | CJ3: µm | CK3: µm | CL3: µm | CM3: µm | CN3: µm | CO3: µm | CP3: µm | CQ3: µm | CR3: µm | CS3: µm | CT3: µm | CU3: µm | CV3: µm | CW3: µm | CX3: <no unit> | CY3: <no unit> | CZ3: <no unit> | DA3: <no unit> | DB3: <no unit> | DC3: <no unit> | DD3: <no unit> | DE3: <no unit> | DF3: mm | DG3: mm | DH3: mm | DI3: mm | DJ3: ° | DK3: ° | DL3: ° | DM3: ° | DN3: % | DO3: % | DP3: % | DQ3: % | DR3: µm | DS3: µm | DT3: µm | DU3: µm | DV3: 1/cm | DW3: 1/cm | DX3: 1/cm | DY3: 1/cm | DZ3: µm | EA3: µm | EB3: µm | EC3: µm | ED3: µm | EE3: µm | EF3: µm | EG3: µm | EH3: µm | EI3: µm | EJ3: µm | EK3: µm | EL3: µm | EM3: µm | EN3: µm | EO3: µm | EP3: µm | EQ3: µm | ER3: µm | ES3: µm | ET3: µm | EU3: µm | EV3: µm | EW3: µm | EX3: µm | EY3: µm | EZ3: µm | FA3: µm | FB3: <no unit> | FC3: <no unit> | FD3: <no unit> | FE3: <no unit> | FF3: <no unit> | FG3: <no unit> | FH3: <no unit> | FI3: <no unit> | FJ3: µm | FK3: µm | FL3: µm | FM3: µm | FN3: µm | FO3: µm | FP3: µm | FQ3: µm | FR3: µm | FS3: µm | FT3: µm | FU3: µm | FV3: µm | FW3: µm | FX3: µm | FY3: µm | FZ3: mm | GA3: mm | GB3: mm | GC3: mm | GD3: ° | GE3: ° | GF3: ° | GG3: ° | GH3: % | GI3: % | GJ3: % | GK3: % | GL3: µm | GM3: µm | GN3: µm | GO3: µm | GP3: % | GQ3: % | GR3: % | GS3: % | GT3: 1/cm | GU3: 1/cm | GV3: 1/cm | GW3: 1/cm | GX3: µm | GY3: µm | GZ3: µm | HA3: µm | HB3: µm | HC3: µm | HD3: µm | HE3: µm | HF3: µm | HG3: µm | HH3: µm | HI3: µm | HJ3: µm | HK3: µm | HL3: µm | HM3: µm | HN3: µm | HO3: µm | HP3: µm | HQ3: µm | HR3: µm | HS3: µm | HT3: µm | HU3: µm | HV3: µm | HW3: µm | HX3: µm | HY3: µm | HZ3: <no unit> | IA3: <no unit> | IB3: <no unit> | IC3: <no unit> | ID3: <no unit> | IE3: <no unit> | IF3: <no unit> | IG3: <no unit> | IH3: µm | II3: µm | IJ3: µm | IK3: µm | IL3: µm | IM3: µm | IN3: µm | IO3: µm | IP3: µm | IQ3: µm | IR3: µm | IS3: µm | IT3: µm | IU3: µm | IV3: µm | IW3: µm | IX3: mm | IY3: mm | IZ3: mm | JA3: mm | JB3: ° | JC3: ° | JD3: ° | JE3: ° | JF3: % | JG3: % | JH3: % | JI3: % | JJ3: µm | JK3: µm | JL3: µm | JM3: µm | JN3: % | JO3: % | JP3: % | JQ3: % | JR3: 1/cm | JS3: 1/cm | JT3: 1/cm | JU3: 1/cm | JV3: µm | JW3: µm | JX3: µm | JY3: µm | JZ3: µm | KA3: µm | KB3: µm | KC3: µm | KD3: µm | KE3: µm | KF3: µm | KG3: µm | KH3: µm | KI3: µm | KJ3: µm | KK3: µm | KL3: µm | KM3: µm | KN3: µm | KO3: µm | KP3: µm | KQ3: µm | KR3: µm | KS3: µm | KT3: µm | KU3: µm | KV3: µm | KW3: µm | KX3: <no unit> | KY3: <no unit> | KZ3: <no unit> | LA3: <no unit> | LB3: <no unit> | LC3: <no unit> | LD3: <no unit> | LE3: <no unit> | LF3: mm | LG3: mm | LH3: mm | LI3: mm | LJ3: ° | LK3: ° | LL3: ° | LM3: ° | LN3: % | LO3: % | LP3: % | LQ3: % | LR3: µm | LS3: µm | LT3: µm | LU3: µm | LV3: % | LW3: % | LX3: % | LY3: % | LZ3: 1/cm | MA3: 1/cm | MB3: 1/cm | MC3: 1/cm | MD3: µm | ME3: µm | MF3: µm | MG3: µm | MH3: µm | MI3: µm | MJ3: µm | MK3: µm | ML3: µm | MM3: µm | MN3: µm | MO3: µm | MP3: µm | MQ3: µm | MR3: µm | MS3: µm | MT3: µm | MU3: µm | MV3: µm | MW3: µm | MX3: µm | MY3: µm | MZ3: µm | NA3: µm | NB3: µm | NC3: µm | ND3: µm | NE3: µm | NF3: <no unit> | NG3: <no unit> | NH3: <no unit> | NI3: <no unit> | NJ3: <no unit> | NK3: <no unit> | NL3: <no unit> | NM3: <no unit> | NN3: mm | NO3: mm | NP3: mm | NQ3: mm | NR3: ° | NS3: ° | NT3: ° | NU3: ° | NV3: % | NW3: % | NX3: % | NY3: % | NZ3: µm | OA3: µm | OB3: µm | OC3: µm | OD3: % | OE3: % | OF3: % | OG3: % | OH3: 1/cm | OI3: 1/cm | OJ3: 1/cm | OK3: 1/cm | OL3: µm | OM3: <no unit> | ON3: <no unit> | OO3: µm | OP3: µm | OQ3: µm | OR3: µm | OS3: mm³/mm² | OT3: mm³/mm² | OU3: mm³/mm² | OV3: mm³/mm² | OW3: mm³/mm² | OX3: mm³/mm² | OY3: µm | OZ3: µm | PA3: µm | PB3: % | PC3: % | PD3: µm | PE3: <no unit> | PF3: <no unit> | PG3: µm | PH3: µm | PI3: µm | PJ3: µm | PK3: mm³/mm² | PL3: mm³/mm² | PM3: mm³/mm² | PN3: mm³/mm² | PO3: mm³/mm² | PP3: mm³/mm² | PQ3: µm | PR3: µm | PS3: µm | PT3: % | PU3: % | PV3: µm | PW3: µm | PX3: µm | PY3: % | PZ3: % | QA3: µm | QB3: µm | QC3: µm | QD3: % | QE3: % | QF3: mm³/mm² | QG3: mm³/mm² | QH3: mm³/mm² | QI3: mm³/mm² | QJ3: mm³/mm² | QK3: mm³/mm² | QL3: mm³/mm² | QM3: mm³/mm² | QN3: % | QO3: ° | QP3: ° | QQ3: ° | QR3: % | QS3: ° | QT3: ° | QU3: °
A4: C45_5x5\C45_5x5\C45_TF\C45_5x5 --- C45_TF_x10_conf_blue_5x5.mnt | B4: 1.1383322e-11 | C4: 8.5491157e-12 | D4: 0.049975264 | E4: 0.096189339 | F4: 0.47766541 | G4: 0.15351674 | H4: 0.29547966 | I4: 1.4673187 | J4: 32.50365 | K4: 32.553625 | L4: 32.553625 | M4: 32.553625 | N4: 32.457436 | O4: 32.553625 | P4: 32.075959 | Q4: 32.553625 | R4: 4.0615357 | S4: 0.57566693 | T4: 2.8224021 | U4: 5.993511 | V4: 5.1039729 | W4: 0.98577405 | X4: 2.7280808 | Y4: 7.5538372 | Z4: 9.1655086 | AA4: 1.1906637 | AB4: 6.008039 | AC4: 11.467016 | AD4: 2.6242575 | AE4: 0.51690637 | AF4: 1.5756111 | AG4: 4.4860107 | AH4: 9.1655086 | AI4: 1.1906637 | AJ4: 6.008039 | AK4: 11.467016 | AL4: 1.481582 | AM4: 0.26889387 | AN4: 0.9238483 | AO4: 2.2457331 | AP4: 1.8218759 | AQ4: 0.30685548 | AR4: 1.1482682 | AS4: 2.7026789 | AT4: -0.21600119 | AU4: 0.38365942 | AV4: -1.9336385 | AW4: 0.54144469 | AX4: 2.7188979 | AY4: 0.71618497 | AZ4: 1.7399663 | BA4: 7.8179157 | BB4: 0.21674872 | BC4: 0.077417513 | BD4: 0.098645357 | BE4: 0.60873333 | BF4: 6.4105065 | BG4: 0.66664744 | BH4: 4.5827623 | BI4: 9.0579801 | BJ4: 4.112591 | BK4: 2.5745626 | BL4: 0.17691287 | BM4: 14.396285 | BN4: 3.208839 | BO4: 0.68521294 | BP4: 1.5469678 | BQ4: 5.2780441 | BR4: 51.059919 | BS4: 15.413079 | BT4: 16.427555 | BU4: 101.37325 | BV4: 3.7062505 | BW4: 0.52395658 | BX4: 2.5959837 | BY4: 5.3020075 | BZ4: 4.7812699 | CA4: 0.68546112 | CB4: 2.728049 | CC4: 6.1695944 | CD4: 8.4875204 | CE4: 0.75348088 | CF4: 5.925852 | CG4: 9.252483 | CH4: 2.5237056 | CI4: 0.47237303 | CJ4: 1.5632608 | CK4: 4.3896862 | CL4: 8.4875204 | CM4: 0.75348088 | CN4: 5.925852 | CO4: 9.252483 | CP4: 1.4732144 | CQ4: 0.26281353 | CR4: 0.9238483 | CS4: 2.2285533 | CT4: 1.804579 | CU4: 0.29095293 | CV4: 1.1482682 | CW4: 2.5823185 | CX4: -0.20281467 | CY4: 0.3636527 | CZ4: -1.7880049 | DA4: 0.51121348 | DB4: 2.6394707 | DC4: 0.64240409 | DD4: 1.7330792 | DE4: 6.98827 | DF4: 0.20925283 | DG4: 0.075055892 | DH4: 0.093489152 | DI4: 0.60858 | DJ4: 6.3872659 | DK4: 0.6631692 | DL4: 4.5827623 | DM4: 8.9092569 | DN4: 7.4617417 | DO4: 3.4905179 | DP4: 1.0614772 | DQ4: 18.133569 | DR4: 3.2076603 | DS4: 0.68491696 | DT4: 1.547125 | DU4: 5.2779989 | DV4: 52.744253 | DW4: 15.542854 | DX4: 16.431694 | DY4: 106.96428 | DZ4: 2.4914421 | EA4: 0.38811814 | EB4: 1.5696853 | EC4: 3.9307374 | ED4: 2.245926 | EE4: 0.34564153 | EF4: 1.5070423 | EG4: 3.3864616 | EH4: 4.7373681 | EI4: 0.64407291 | EJ4: 3.0767276 | EK4: 6.671048 | EL4: 1.7445872 | EM4: 0.22784847 | EN4: 1.2821383 | EO4: 2.44382 | EP4: 7.5676523 | EQ4: 1.354983 | ER4: 3.957995 | ES4: 11.656221 | ET4: 0.71013537 | EU4: 0.094265836 | EV4: 0.51300826 | EW4: 0.99375383 | EX4: 0.91222289 | EY4: 0.12520196 | EZ4: 0.62378581 | FA4: 1.3327074 | FB4: 0.20449238 | FC4: 0.20937742 | FD4: -0.42224477 | FE4: 0.93773072 | FF4: 3.4577797 | FG4: 0.6063693 | FH4: 2.5145165 | FI4: 8.3327899 | FJ4: 3.9190752 | FK4: 0.87773211 | FL4: 2.0403893 | FM4: 7.3681984 | FN4: 3.6485771 | FO4: 0.8014745 | FP4: 1.9176057 | FQ4: 6.1030596 | FR4: 7.1720062 | FS4: 1.2547989 | FT4: 3.957995 | FU4: 10.706331 | FV4: 5.2928473 | FW4: 1.6287822 | FX4: 2.436223 | FY4: 10.539673 | FZ4: 0.086327581 | GA4: 0.013839515 | GB4: 0.061805393 | GC4: 0.12692791 | GD4: 6.1783449 | GE4: 0.66076662 | GF4: 4.5324083 | GG4: 9.1791392 | GH4: 1.2821608 | GI4: 1.1378963 | GJ4: 0.049248953 | GK4: 5.8852499 | GL4: 1.3392036 | GM4: 0.17453599 | GN4: 0.93891565 | GO4: 1.9459365 | GP4: 9.2409441 | GQ4: 1.5886614 | GR4: 5.6143807 | GS4: 14.571012 | GT4: 118.73117 | GU4: 18.382237 | GV4: 78.784881 | GW4: 161.79818 | GX4: 2.4220145 | GY4: 0.36248762 | GZ4: 1.5696853 | HA4: 3.7436291 | HB4: 2.2132579 | HC4: 0.33065539 | HD4: 1.5070423 | HE4: 3.3849637 | HF4: 4.6352724 | HG4: 0.5992016 | HH4: 3.0767276 | HI4: 6.4356534 | HJ4: 1.7104731 | HK4: 0.21659712 | HL4: 1.2486827 | HM4: 2.3864168 | HN4: 7.2757283 | HO4: 1.1912075 | HP4: 3.957995 | HQ4: 11.343584 | HR4: 0.7049282 | HS4: 0.091464638 | HT4: 0.51300826 | HU4: 0.9692188 | HV4: 0.90310254 | HW4: 0.12024376 | HX4: 0.62378581 | HY4: 1.3099344 | HZ4: 0.19724206 | IA4: 0.21049005 | IB4: -0.44035708 | IC4: 1.0784703 | ID4: 3.4106317 | IE4: 0.62209113 | IF4: 2.5145165 | IG4: 9.0936717 | IH4: 3.7298416 | II4: 0.81916 | IJ4: 2.0312298 | IK4: 7.3184104 | IL4: 3.5458866 | IM4: 0.73655821 | IN4: 1.9176057 | IO4: 5.8638948 | IP4: 6.8729093 | IQ4: 1.0422166 | IR4: 3.957995 | IS4: 9.404891 | IT4: 5.1113637 | IU4: 1.4466654 | IV4: 2.224185 | IW4: 8.83932 | IX4: 0.084520802 | IY4: 0.013340696 | IZ4: 0.061805393 | JA4: 0.12679571 | JB4: 6.1573693 | JC4: 0.65709825 | JD4: 4.5324083 | JE4: 9.0415854 | JF4: 1.5757684 | JG4: 1.4092968 | JH4: 0.049248953 | JI4: 9.6544688 | JJ4: 1.3373419 | JK4: 0.17304256 | JL4: 0.93891565 | JM4: 1.8968822 | JN4: 9.5080186 | JO4: 1.5863676 | JP4: 6.3703548 | JQ4: 15.488796 | JR4: 121.15489 | JS4: 18.321224 | JT4: 78.867019 | JU4: 161.79818 | JV4: 2.3282856 | JW4: 0.53797776 | JX4: 1.0316987 | JY4: 4.6876714 | JZ4: 2.8401062 | KA4: 0.81204828 | KB4: 1.2429064 | KC4: 5.2221688 | KD4: 5.1683918 | KE4: 1.1302132 | KF4: 2.414544 | KG4: 9.031254 | KH4: 3.8769462 | KI4: 1.3278534 | KJ4: 1.4610487 | KK4: 9.031254 | KL4: 5.1683918 | KM4: 1.1302132 | KN4: 2.414544 | KO4: 9.031254 | KP4: 1.0666071 | KQ4: 0.26161303 | KR4: 0.50660742 | KS4: 1.9049404 | KT4: 1.2997241 | KU4: 0.30162903 | KV4: 0.66384267 | KW4: 2.3268476 | KX4: -0.26865692 | KY4: 0.44208135 | KZ4: -1.7770295 | LA4: 0.83663658 | LB4: 2.5734828 | LC4: 0.72366839 | LD4: 1.551001 | LE4: 5.9775032 | LF4: 1.9662217 | LG4: 0.71944151 | LH4: 0.7383 | LI4: 4.83276 | LJ4: 0.26373135 | LK4: 0.054097333 | LL4: 0.1281687 | LM4: 0.42981982 | LN4: 19.313298 | LO4: 9.2376084 | LP4: 3.1402035 | LQ4: 60.128262 | LR4: 2.3289174 | LS4: 0.67710847 | LT4: 0.91389132 | LU4: 4.8183546 | LV4: 17.255896 | LW4: 5.7616198 | LX4: 3.4940292 | LY4: 32.99425 | LZ4: 5.6714288 | MA4: 1.8147231 | MB4: 2.069211 | MC4: 13.54463 | MD4: 2.3128462 | ME4: 0.52493266 | MF4: 1.0316987 | MG4: 4.4269398 | MH4: 2.7883755 | MI4: 0.738034 | MJ4: 1.2408664 | MK4: 5.1407438 | ML4: 5.1012217 | MM4: 1.044032 | MN4: 2.414544 | MO4: 8.07165 | MP4: 3.8298571 | MQ4: 1.2591604 | MR4: 1.4610297 | MS4: 8.07165 | MT4: 5.1012217 | MU4: 1.044032 | MV4: 2.414544 | MW4: 8.07165 | MX4: 1.0602844 | MY4: 0.25555676 | MZ4: 0.50660742 | NA4: 1.8223238 | NB4: 1.2894678 | NC4: 0.29032467 | ND4: 0.66379508 | NE4: 2.2131994 | NF4: -0.2574898 | NG4: 0.43408654 | NH4: -1.7160459 | NI4: 0.83906041 | NJ4: 2.5462448 | NK4: 0.70302098 | NL4: 1.5505603 | NM4: 5.723534 | NN4: 1.9662655 | NO4: 0.71923896 | NP4: 0.73692 | NQ4: 4.86036 | NR4: 0.2614058 | NS4: 0.051682116 | NT4: 0.1281687 | NU4: 0.40160167 | NV4: 19.465936 | NW4: 9.1817849 | NX4: 3.1180893 | NY4: 60.128262 | NZ4: 2.3231095 | OA4: 0.6722919 | OB4: 0.90724139 | OC4: 4.7785782 | OD4: 17.453762 | OE4: 5.7047153 | OF4: 3.7593985 | OG4: 32.972136 | OH4: 5.6705003 | OI4: 1.8129066 | OJ4: 2.0574608 | OK4: 13.569994 | OL4: 1.7150504 | OM4: -0.35834951 | ON4: 3.0243641 | OO4: 5.974959 | OP4: 7.457196 | OQ4: 13.432155 | OR4: 1.37019 | OS4: 6.1003073e-05 | OT4: 0.0022015506 | OU4: 6.1003073e-05 | OV4: 0.001577768 | OW4: 0.001979663 | OX4: 0.00022188757 | OY4: 4.371934 | OZ4: 1.1457787 | PA4: 1.987914 | PB4: 8.2626237 | PC4: 88.152904 | PD4: 1.696242 | PE4: -0.32194401 | PF4: 2.8428443 | PG4: 5.404155 | PH4: 6.126288 | PI4: 11.530443 | PJ4: 1.3622275 | PK4: 5.8889841e-05 | PL4: 0.0021933282 | PM4: 5.8889841e-05 | PN4: 0.0015767118 | PO4: 0.0019762962 | PP4: 0.00021703197 | PQ4: 4.3686526 | PR4: 1.0961498 | PS4: 1.9056278 | PT4: 8.2208094 | PU4: 88.140803 | PV4: 5.0269032 | PW4: 0.98163286 | PX4: 2.1559055 | PY4: 8.5841172 | PZ4: 88.671976 | QA4: 5.0266135 | QB4: 0.92765681 | QC4: 2.0606711 | QD4: 8.5474644 | QE4: 88.67444 | QF4: 5.396909e-05 | QG4: 0.0018120458 | QH4: 0.0023055282 | QI4: 0.0002424924 | QJ4: 5.1679037e-05 | QK4: 0.0018112972 | QL4: 0.0023038338 | QM4: 0.00023702268 | QN4: 14.562343 | QO4: 0.029635386 | QP4: 4.9753212 | QQ4: 173.76159 | QR4: 14.503951 | QS4: 0.027767179 | QT4: 5.4645015 | QU4: 173.76284
A5: C45_5x5\C45_5x5\C45_TF\C45_5x5 --- C45_TF_x10_conf_green_5x5.mnt | B5: 1.1195111e-11 | C5: 1.0888888e-11 | D5: 0.034882895 | E5: 0.081717803 | F5: 0.47417846 | G5: 0.10715518 | H5: 0.2510252 | I5: 1.4566072 | J5: 32.518742 | K5: 32.553625 | L5: 32.553625 | M5: 32.553625 | N5: 32.471907 | O5: 32.553625 | P5: 32.079446 | Q5: 32.553625 | R5: 4.1420262 | S5: 0.57733905 | T5: 2.8393311 | U5: 5.9760481 | V5: 5.7146025 | W5: 1.0818115 | X5: 3.4369408 | Y5: 7.9791964 | Z5: 9.8566287 | AA5: 1.2619152 | AB5: 6.982278 | AC5: 11.865149 | AD5: 2.8363811 | AE5: 0.54012847 | AF5: 1.7318367 | AG5: 5.0659648 | AH5: 9.8566287 | AI5: 1.2619152 | AJ5: 6.982278 | AK5: 11.865149 | AL5: 1.5392395 | AM5: 0.27172958 | AN5: 0.96570208 | AO5: 2.3128349 | AP5: 1.897307 | AQ5: 0.31063575 | AR5: 1.1659954 | AS5: 2.6920552 | AT5: -0.22343086 | AU5: 0.37100207 | AV5: -1.836189 | AW5: 0.53562172 | AX5: 2.7634359 | AY5: 0.66210374 | AZ5: 1.7346099 | BA5: 6.9728139 | BB5: 0.20129678 | BC5: 0.064047331 | BD5: 0.082408656 | BE5: 0.483805 | BF5: 6.8719346 | BG5: 0.73820029 | BH5: 4.7816186 | BI5: 9.2170418 | BJ5: 4.5407749 | BK5: 2.5278316 | BL5: 0.37593985 | BM5: 13.268465 | BN5: 3.3272293 | BO5: 0.6924354 | BP5: 1.808778 | BQ5: 5.4756545 | BR5: 54.160623 | BS5: 15.624295 | BT5: 20.669485 | BU5: 121.34648 | BV5: 3.8568605 | BW5: 0.52776798 | BX5: 2.7376824 | BY5: 5.3943029 | BZ5: 5.117017 | CA5: 0.63434168 | CB5: 3.4369408 | CC5: 6.3421431 | CD5: 8.9738775 | CE5: 0.68246041 | CF5: 6.982278 | CG5: 9.598256 | CH5: 2.7097543 | CI5: 0.47349693 | CJ5: 1.7318367 | CK5: 4.7706632 | CL5: 8.9738775 | CM5: 0.68246041 | CN5: 6.982278 | CO5: 9.598256 | CP5: 1.5301573 | CQ5: 0.26574062 | CR5: 0.96440731 | CS5: 2.3071582 | CT5: 1.8776355 | CU5: 0.29486354 | CV5: 1.1659954 | CW5: 2.6074215 | CX5: -0.19827333 | CY5: 0.34654286 | CZ5: -1.6518279 | DA5: 0.50361586 | DB5: 2.6494444 | DC5: 0.56150201 | DD5: 1.7135282 | DE5: 5.9646034 | DF5: 0.19233507 | DG5: 0.060390483 | DH5: 0.082408656 | DI5: 0.462576 | DJ5: 6.8410141 | DK5: 0.72808054 | DL5: 4.7816186 | DM5: 9.155236 | DN5: 7.1145547 | DO5: 3.251278 | DP5: 0.7518797 | DQ5: 16.771895 | DR5: 3.3258155 | DS5: 0.69234392 | DT5: 1.8086027 | DU5: 5.4760471 | DV5: 56.528697 | DW5: 15.985004 | DX5: 21.618069 | DY5: 121.34648 | DZ5: 2.5409285 | EA5: 0.38566215 | EB5: 1.473104 | EC5: 3.9363773 | ED5: 2.6773571 | EE5: 0.42157946 | EF5: 1.7484075 | EG5: 4.2596916 | EH5: 5.2182856 | EI5: 0.71539628 | EJ5: 3.4086461 | EK5: 7.5391713 | EL5: 1.951172 | EM5: 0.26111505 | EN5: 1.3176162 | EO5: 2.9715065 | EP5: 8.1170534 | EQ5: 1.4060515 | ER5: 4.337118 | ES5: 12.323727 | ET5: 0.76799843 | EU5: 0.098374877 | EV5: 0.56800366 | EW5: 1.0582462 | EX5: 0.98760773 | EY5: 0.13135512 | EZ5: 0.68778635 | FA5: 1.3863416 | FB5: 0.030481721 | FC5: 0.20885176 | FD5: -0.48215539 | FE5: 0.77808777 | FF5: 3.466975 | FG5: 0.45929614 | FH5: 2.6413535 | FI5: 4.9724353 | FJ5: 3.9176696 | FK5: 0.82589245 | FL5: 1.8847223 | FM5: 6.41278 | FN5: 4.1993838 | FO5: 0.92370217 | FP5: 2.4523957 | FQ5: 7.6432541 | FR5: 7.6200111 | FS5: 1.3244692 | FT5: 3.918726 | FU5: 11.301657 | FV5: 5.826095 | FW5: 1.6370975 | FX5: 2.495877 | FY5: 10.98702 | FZ5: 0.084333311 | GA5: 0.013593674 | GB5: 0.061515529 | GC5: 0.15203657 | GD5: 6.707355 | GE5: 0.73271283 | GF5: 4.6853829 | GG5: 9.2718424 | GH5: 1.4669569 | GI5: 1.3842858 | GJ5: 0.049248953 | GK5: 10.416154 | GL5: 1.4579304 | GM5: 0.18279244 | GN5: 1.0256813 | GO5: 2.0104379 | GP5: 8.8286924 | GQ5: 1.6899532 | GR5: 5.269638 | GS5: 14.774686 | GT5: 121.43831 | GU5: 18.162201 | GV5: 65.773649 | GW5: 162.56058 | GX5: 2.4854212 | GY5: 0.36209827 | GZ5: 1.473104 | HA5: 3.7527144 | HB5: 2.5988079 | HC5: 0.3835647 | HD5: 1.7484075 | HE5: 4.0618704 | HF5: 5.0842291 | HG5: 0.64737035 | HH5: 3.4086461 | HI5: 7.3333259 | HJ5: 1.9081854 | HK5: 0.23923237 | HL5: 1.3176162 | HM5: 2.9430202 | HN5: 7.6926184 | HO5: 1.1733221 | HP5: 4.337118 | HQ5: 10.952397 | HR5: 0.76219476 | HS5: 0.095742011 | HT5: 0.56800366 | HU5: 1.0536471 | HV5: 0.97629965 | HW5: 0.12582177 | HX5: 0.68778635 | HY5: 1.3751341 | HZ5: 0.037516408 | IA5: 0.20729398 | IB5: -0.49381414 | IC5: 0.80041426 | ID5: 3.3948088 | IE5: 0.44188902 | IF5: 2.6361616 | IG5: 4.9720053 | IH5: 3.7621079 | II5: 0.76325161 | IJ5: 1.8847223 | IK5: 6.3210595 | IL5: 3.9305105 | IM5: 0.75864907 | IN5: 2.4523957 | IO5: 6.2693867 | IP5: 7.2346645 | IQ5: 1.0620824 | IR5: 3.918726 | IS5: 10.103537 | IT5: 5.6310988 | IU5: 1.3790698 | IV5: 2.45233 | IW5: 9.034487 | IX5: 0.082575151 | IY5: 0.013177065 | IZ5: 0.058444468 | JA5: 0.15203657 | JB5: 6.6835815 | JC5: 0.72638181 | JD5: 4.6853829 | JE5: 9.2083755 | JF5: 1.6837328 | JG5: 1.4458611 | JH5: 0.07387343 | JI5: 10.416154 | JJ5: 1.4576235 | JK5: 0.18320706 | JL5: 1.0271999 | JM5: 2.0103328 | JN5: 9.1411947 | JO5: 1.6534205 | JP5: 5.3411346 | JQ5: 14.774686 | JR5: 123.92279 | JS5: 18.121055 | JT5: 65.773649 | JU5: 171.10259 | JV5: 2.3877285 | JW5: 0.54392811 | JX5: 0.97947681 | JY5: 4.5459661 | JZ5: 2.8911197 | KA5: 0.83513266 | KB5: 1.2536948 | KC5: 5.4498247 | KD5: 5.2788482 | KE5: 1.157673 | KF5: 2.306001 | KG5: 9.084519 | KH5: 3.9303744 | KI5: 1.3015528 | KJ5: 1.5411787 | KK5: 9.084519 | KL5: 5.2788482 | KM5: 1.157673 | KN5: 2.306001 | KO5: 9.084519 | KP5: 1.0973128 | KQ5: 0.26809118 | KR5: 0.51615586 | KS5: 1.8581008 | KT5: 1.3357433 | KU5: 0.31034595 | KV5: 0.67020965 | KW5: 2.2886375 | KX5: -0.2512349 | KY5: 0.4429136 | KZ5: -1.7984259 | LA5: 0.90194668 | LB5: 2.5459863 | LC5: 0.71948486 | LD5: 1.566093 | LE5: 6.1985441 | LF5: 1.9795645 | LG5: 0.6985788 | LH5: 0.55752 | LI5: 4.58022 | LJ5: 0.27046853 | LK5: 0.054932469 | LL5: 0.12320245 | LM5: 0.4402191 | LN5: 18.969143 | LO5: 9.206909 | LP5: 3.3171163 | LQ5: 63.003096 | LR5: 2.406233 | LS5: 0.68658829 | LT5: 0.92572287 | LU5: 4.3849404 | LV5: 17.663629 | LW5: 5.8585074 | LX5: 0 | LY5: 32.99425 | LZ5: 5.6359611 | MA5: 1.9333703 | MB5: 2.1833012 | MC5: 17.936576 | MD5: 2.3751371 | ME5: 0.53701935 | MF5: 0.97947681 | MG5: 4.4656677 | MH5: 2.8364173 | MI5: 0.75685904 | MJ5: 1.2560159 | MK5: 5.2847305 | ML5: 5.2115544 | MM5: 1.0722777 | MN5: 2.306001 | MO5: 8.298117 | MP5: 3.8688356 | MQ5: 1.2184918 | MR5: 1.5411787 | MS5: 8.298117 | MT5: 5.2115544 | MU5: 1.0722777 | MV5: 2.306001 | MW5: 8.298117 | MX5: 1.0902277 | MY5: 0.26207899 | MZ5: 0.51615586 | NA5: 1.7878305 | NB5: 1.3247651 | NC5: 0.29910974 | ND5: 0.67020965 | NE5: 2.1877336 | NF5: -0.23894071 | NG5: 0.43554586 | NH5: -1.8186873 | NI5: 0.90153818 | NJ5: 2.5218263 | NK5: 0.6987219 | NL5: 1.566093 | NM5: 6.290178 | NN5: 1.9877423 | NO5: 0.69171601 | NP5: 0.84663 | NQ5: 4.57884 | NR5: 0.26798438 | NS5: 0.052870093 | NT5: 0.12320245 | NU5: 0.41478049 | NV5: 19.046537 | NW5: 9.2097612 | NX5: 3.2950022 | NY5: 63.003096 | NZ5: 2.3966276 | OA5: 0.68006441 | OB5: 0.92572287 | OC5: 4.3382025 | OD5: 17.815416 | OE5: 5.7993673 | OF5: 0 | OG5: 32.99425 | OH5: 5.5652522 | OI5: 1.700688 | OJ5: 2.1839593 | OK5: 11.811535 | OL5: 1.7852291 | OM5: -0.35179667 | ON5: 3.0411743 | OO5: 6.012619 | OP5: 7.859115 | OQ5: 13.871734 | OR5: 1.4252244 | OS5: 6.3774738e-05 | OT5: 0.0023000581 | OU5: 6.3774738e-05 | OV5: 0.0016366413 | OW5: 0.0020695857 | OX5: 0.0002304724 | OY5: 4.5548772 | OZ5: 1.2043687 | PA5: 2.0674852 | PB5: 8.4433722 | PC5: 88.351054 | PD5: 1.7644738 | PE5: -0.30466169 | PF5: 2.8308751 | PG5: 5.436377 | PH5: 6.632064 | PI5: 12.068441 | PJ5: 1.4167109 | PK5: 6.1700038e-05 | PL5: 0.0022932092 | PM5: 6.1700038e-05 | PN5: 0.001636047 | PO5: 0.002068483 | PP5: 0.00022472619 | PQ5: 4.5522013 | PR5: 1.1564918 | PS5: 1.9701952 | PT5: 8.4367627 | PU5: 88.34865 | PV5: 5.2046339 | PW5: 1.0532293 | PX5: 2.2360698 | PY5: 8.8597365 | PZ5: 88.870746 | QA5: 5.2026494 | QB5: 1.0092138 | QC5: 2.1251289 | QD5: 8.8582667 | QE5: 88.885176 | QF5: 5.6990645e-05 | QG5: 0.0018644623 | QH5: 0.0023981307 | QI5: 0.00025145561 | QJ5: 5.4993494e-05 | QK5: 0.0018638453 | QL5: 0.0023972607 | QM5: 0.00024508627 | QN5: 14.175455 | QO5: 0.025451213 | QP5: 5.4558692 | QQ5: 174.78159 | QR5: 14.136506 | QS5: 0.024225518 | QT5: 5.4561747 | QU5: 174.7806
A6: C45_5x5\C45_5x5\C45_TF\C45_5x5 --- C45_TF_x10_conf_red_5x5.mnt | B6: 1.0243047e-11 | C6: 1.0008999e-11 | D6: 0.06289281 | E6: 0.1098934 | F6: 0.50824246 | G6: 0.19319756 | H6: 0.33757654 | I6: 1.5612469 | J6: 32.490732 | K6: 32.553625 | L6: 32.553625 | M6: 32.553625 | N6: 32.443731 | O6: 32.553625 | P6: 32.045382 | Q6: 32.553625 | R6: 4.2939966 | S6: 0.59260719 | T6: 2.874533 | U6: 6.2153807 | V6: 6.2516594 | W6: 1.1228192 | X6: 3.8031927 | Y6: 8.4334704 | Z6: 10.545656 | AA6: 1.3117873 | AB6: 7.435299 | AC6: 12.555881 | AD6: 3.0019591 | AE6: 0.52940133 | AF6: 1.9273222 | AG6: 4.8035805 | AH6: 10.545656 | AI6: 1.3117873 | AJ6: 7.435299 | AK6: 12.555881 | AL6: 1.5933827 | AM6: 0.27368621 | AN6: 0.99675349 | AO6: 2.3790596 | AP6: 1.9672595 | AQ6: 0.31414691 | AR6: 1.2018615 | AS6: 2.7197622 | AT6: -0.2657975 | AU6: 0.35936972 | AV6: -1.7856935 | AW6: 0.43740039 | AX6: 2.8243852 | AY6: 0.65302128 | AZ6: 1.7623058 | BA6: 6.6464537 | BB6: 0.18264963 | BC6: 0.059439788 | BD6: 0.087640952 | BE6: 0.4692 | BF6: 7.6950068 | BG6: 0.83762674 | BH6: 5.581233 | BI6: 10.251795 | BJ6: 3.9994247 | BK6: 2.3129188 | BL6: 0.37593985 | BM6: 11.61358 | BN6: 3.4335042 | BO6: 0.68907075 | BP6: 1.9711387 | BQ6: 5.6999533 | BR6: 59.752294 | BS6: 16.94269 | BT6: 21.312873 | BU6: 114.10191 | BV6: 3.9710088 | BW6: 0.52781942 | BX6: 2.8296729 | BY6: 5.5399049 | BZ6: 5.4663478 | CA6: 0.59755491 | CB6: 3.8031927 | CC6: 6.7972205 | CD6: 9.4373566 | CE6: 0.62585816 | CF6: 7.435299 | CG6: 9.994255 | CH6: 2.8649188 | CI6: 0.4524391 | CJ6: 1.9273222 | CK6: 4.5991359 | CL6: 9.4373566 | CM6: 0.62585816 | CN6: 7.435299 | CO6: 9.994255 | CP6: 1.5825289 | CQ6: 0.26720302 | CR6: 0.99600633 | CS6: 2.3697515 | CT6: 1.9433457 | CU6: 0.29703298 | CV6: 1.2018615 | CW6: 2.6947868 | CX6: -0.23174436 | CY6: 0.33269348 | CZ6: -1.5759125 | DA6: 0.42902051 | DB6: 2.6746254 | DC6: 0.53581189 | DD6: 1.7269661 | DE6: 5.5771747 | DF6: 0.17444403 | DG6: 0.054514031 | DH6: 0.084944307 | DI6: 0.391092 | DJ6: 7.6402975 | DK6: 0.82015546 | DL6: 5.581233 | DM6: 10.118052 | DN6: 6.7231576 | DO6: 3.1234857 | DP6: 0.70765148 | DQ6: 16.076957 | DR6: 3.4315906 | DS6: 0.68874334 | DT6: 1.9711387 | DU6: 5.699005 | DV6: 62.214788 | DW6: 17.104397 | DX6: 25.569431 | DY6: 117.72419 | DZ6: 2.6706858 | EA6: 0.40704405 | EB6: 1.5865391 | EC6: 4.0530751 | ED6: 3.0203438 | EE6: 0.45658377 | EF6: 2.035375 | EG6: 4.7551286 | EH6: 5.6910296 | EI6: 0.76457898 | EJ6: 3.900865 | EK6: 8.2219859 | EL6: 2.1394199 | EM6: 0.27071747 | EN6: 1.5446978 | EO6: 3.0559003 | EP6: 8.6863531 | EQ6: 1.4929591 | ER6: 4.821726 | ES6: 12.390907 | ET6: 0.82519233 | EU6: 0.10393759 | EV6: 0.60905028 | EW6: 1.1712901 | EX6: 1.0618091 | EY6: 0.13695516 | EZ6: 0.74828979 | FA6: 1.5471607 | FB6: -0.077884617 | FC6: 0.20716828 | FD6: -0.54857984 | FE6: 0.62492778 | FF6: 3.4992145 | FG6: 0.45517752 | FH6: 2.6126804 | FI6: 5.450119 | FJ6: 4.0557571 | FK6: 0.83664555 | FL6: 1.9436808 | FM6: 6.5832906 | FN6: 4.6305959 | FO6: 1.0158151 | FP6: 2.7987475 | FQ6: 7.8041689 | FR6: 8.1946805 | FS6: 1.4157308 | FT6: 4.33872 | FU6: 11.767516 | FV6: 6.3450249 | FW6: 1.7719482 | FX6: 2.617568 | FY6: 11.567386 | FZ6: 0.080097047 | GA6: 0.01167328 | GB6: 0.059755484 | GC6: 0.11404085 | GD6: 7.5241517 | GE6: 0.83567175 | GF6: 5.4948555 | GG6: 10.325369 | GH6: 1.344338 | GI6: 1.3336759 | GJ6: 0.049248953 | GK6: 10.365578 | GL6: 1.5802383 | GM6: 0.20120365 | GN6: 1.1360974 | GO6: 2.1952036 | GP6: 8.4499972 | GQ6: 1.7007678 | GR6: 4.8263974 | GS6: 14.553066 | GT6: 127.42923 | GU6: 17.936377 | GV6: 87.687876 | GW6: 167.34866 | GX6: 2.6085976 | GY6: 0.38402849 | GZ6: 1.5865391 | HA6: 3.8700042 | HB6: 2.9094318 | HC6: 0.39489015 | HD6: 2.035375 | HE6: 4.347096 | HF6: 5.5180294 | HG6: 0.67593994 | HH6: 3.900865 | HI6: 7.7955479 | HJ6: 2.0871462 | HK6: 0.25030819 | HL6: 1.5430318 | HM6: 2.9098236 | HN6: 8.1969177 | HO6: 1.222066 | HP6: 4.821726 | HQ6: 11.342618 | HR6: 0.81795186 | HS6: 0.10040134 | HT6: 0.60905028 | HU6: 1.14999 | HV6: 1.0473204 | HW6: 0.12965382 | HX6: 0.74828979 | HY6: 1.5041464 | HZ6: -0.063890575 | IA6: 0.20415664 | IB6: -0.56302139 | IC6: 0.67224306 | ID6: 3.4064901 | IE6: 0.4356821 | IF6: 2.6126804 | IG6: 5.3992322 | IH6: 3.8979461 | II6: 0.78820644 | IJ6: 1.9436808 | IK6: 6.4563169 | IL6: 4.2989715 | IM6: 0.79224273 | IN6: 2.7987475 | IO6: 6.4880597 | IP6: 7.7058249 | IQ6: 1.0898664 | IR6: 4.33872 | IS6: 10.898911 | IT6: 6.0991904 | IU6: 1.4762306 | IV6: 2.617566 | IW6: 9.399209 | IX6: 0.078416373 | IY6: 0.011316869 | IZ6: 0.059755484 | JA6: 0.11404085 | JB6: 7.4803925 | JC6: 0.81876003 | JD6: 5.4948555 | JE6: 10.223827 | JF6: 1.5693422 | JG6: 1.4181144 | JH6: 0.049248953 | JI6: 10.365578 | JJ6: 1.579377 | JK6: 0.20122341 | JL6: 1.1359924 | JM6: 2.1945015 | JN6: 8.8227897 | JO6: 1.7015281 | JP6: 4.9987688 | JQ6: 14.553066 | JR6: 130.08009 | JS6: 17.935581 | JT6: 87.687876 | JU6: 167.34866 | JV6: 2.4246908 | JW6: 0.5448583 | JX6: 0.96568808 | JY6: 4.3152203 | JZ6: 2.9507976 | KA6: 0.86459155 | KB6: 1.2858569 | KC6: 5.5842027 | KD6: 5.3754884 | KE6: 1.1760934 | KF6: 2.251545 | KG6: 8.986346 | KH6: 3.994703 | KI6: 1.3107916 | KJ6: 1.523843 | KK6: 8.986346 | KL6: 5.3754884 | KM6: 1.1760934 | KN6: 2.251545 | KO6: 8.986346 | KP6: 1.1208139 | KQ6: 0.27135951 | KR6: 0.52821086 | KS6: 1.8534786 | KT6: 1.363865 | KU6: 0.31475342 | KV6: 0.68777991 | KW6: 2.286494 | KX6: -0.25079806 | KY6: 0.44711514 | KZ6: -1.8518135 | LA6: 0.93279192 | LB6: 2.5383728 | LC6: 0.70565568 | LD6: 1.5868856 | LE6: 6.1916118 | LF6: 2.0091566 | LG6: 0.73943058 | LH6: 0.849735 | LI6: 4.5816 | LJ6: 0.27676678 | LK6: 0.055816311 | LL6: 0.12497815 | LM6: 0.44483896 | LN6: 18.71254 | LO6: 9.1025259 | LP6: 3.4276869 | LQ6: 63.056052 | LR6: 2.4567438 | LS6: 0.69800412 | LT6: 0.97672448 | LU6: 4.4008125 | LV6: 17.875345 | LW6: 5.8514613 | LX6: 1.4864943 | LY6: 32.529854 | LZ6: 5.552459 | MA6: 1.7325684 | MB6: 2.1826436 | MC6: 11.768375 | MD6: 2.4097924 | ME6: 0.53787094 | MF6: 0.96568808 | MG6: 4.2562637 | MH6: 2.8911433 | MI6: 0.78338992 | MJ6: 1.2858569 | MK6: 5.3585524 | ML6: 5.3009357 | MM6: 1.0891197 | MN6: 2.251545 | MO6: 8.310553 | MP6: 3.9388692 | MQ6: 1.2338356 | MR6: 1.523843 | MS6: 7.877502 | MT6: 5.3009357 | MU6: 1.0891197 | MV6: 2.251545 | MW6: 8.310553 | MX6: 1.1122289 | MY6: 0.26498355 | MZ6: 0.52821086 | NA6: 1.7931004 | NB6: 1.3509896 | NC6: 0.30323813 | ND6: 0.68777991 | NE6: 2.196587 | NF6: -0.23773864 | NG6: 0.43956119 | NH6: -1.8851937 | NI6: 0.93121187 | NJ6: 2.5141435 | NK6: 0.6863504 | NL6: 1.5868802 | NM6: 6.3544689 | NN6: 2.0147444 | NO6: 0.73641712 | NP6: 0.849735 | NQ6: 4.5816 | NR6: 0.27389876 | NS6: 0.053762547 | NT6: 0.12497815 | NU6: 0.4239624 | NV6: 18.825872 | NW6: 9.0883284 | NX6: 3.4055728 | NY6: 63.056052 | NZ6: 2.4437306 | OA6: 0.68995816 | OB6: 0.97415059 | OC6: 4.3372572 | OD6: 18.02687 | OE6: 5.7832223 | OF6: 2.034498 | OG6: 32.529854 | OH6: 5.5298137 | OI6: 1.7183938 | OJ6: 2.1826436 | OK6: 11.768375 | OL6: 1.8547525 | OM6: -0.39014919 | ON6: 3.1099598 | OO6: 6.126929 | OP6: 8.390272 | OQ6: 14.517201 | OR6: 1.4786069 | OS6: 6.4848324e-05 | OT6: 0.0023764282 | OU6: 6.4848324e-05 | OV6: 0.0016964036 | OW6: 0.0021334794 | OX6: 0.00024294889 | OY6: 4.7152196 | OZ6: 1.2174662 | PA6: 2.1977144 | PB6: 8.2670977 | PC6: 88.209329 | PD6: 1.8300081 | PE6: -0.33217808 | PF6: 2.8549168 | PG6: 5.604222 | PH6: 6.945401 | PI6: 12.549623 | PJ6: 1.4685798 | PK6: 6.2595035e-05 | PL6: 0.0023683745 | PM6: 6.2595035e-05 | PN6: 0.0016958051 | PO6: 0.0021324359 | PP6: 0.00023593853 | PQ6: 4.7115421 | PR6: 1.1639869 | PS6: 2.0835825 | PT6: 8.2759061 | PU6: 88.221208 | PV6: 5.3793309 | PW6: 1.056706 | PX6: 2.3581236 | PY6: 8.5886511 | PZ6: 88.786664 | QA6: 5.3774729 | QB6: 1.007024 | QC6: 2.2257466 | QD6: 8.5965533 | QE6: 88.803756 | QF6: 5.7928626e-05 | QG6: 0.0019243509 | QH6: 0.0024609631 | QI6: 0.00026375205 | QJ6: 5.5783392e-05 | QK6: 0.0019234212 | QL6: 0.0024601498 | QM6: 0.00025612309 | QN6: 14.292919 | QO6: 0.022509396 | QP6: 5.4587023 | QQ6: 174.78299 | QR6: 14.260981 | QS6: 0.021516835 | QT6: 5.4582844 | QU6: 174.78241
A7: C45_5x5\C45_5x5\C45_TF\C45_5x5 --- C45_TF_x10_fusion_blue_5x5.mnt | B7: 1.1839685e-11 | C7: 1.1682655e-11 | D7: 0.0010588464 | E7: 0.056722554 | F7: 0.49893756 | G7: 0.0032526221 | H7: 0.17424343 | I7: 1.5326636 | J7: 32.552566 | K7: 32.553625 | L7: 32.553625 | M7: 32.553625 | N7: 32.496902 | O7: 32.553625 | P7: 32.054687 | Q7: 32.553625 | R7: 4.7858014 | S7: 0.77852759 | T7: 2.9887885 | U7: 6.9434862 | V7: 5.5009768 | W7: 0.95272611 | X7: 3.0668142 | Y7: 7.6795637 | Z7: 10.286778 | AA7: 1.3231177 | AB7: 6.316528 | AC7: 12.699506 | AD7: 2.7334566 | AE7: 0.48550052 | AF7: 1.7826016 | AG7: 4.3632315 | AH7: 10.286778 | AI7: 1.3231177 | AJ7: 6.316528 | AK7: 12.699506 | AL7: 1.5155022 | AM7: 0.26291664 | AN7: 0.97610346 | AO7: 2.2781167 | AP7: 1.8666522 | AQ7: 0.30039299 | AR7: 1.1962458 | AS7: 2.7446 | AT7: -0.2053074 | AU7: 0.36532673 | AV7: -1.8017506 | AW7: 0.53939282 | AX7: 2.750737 | AY7: 0.67939369 | AZ7: 1.7846873 | BA7: 7.443541 | BB7: 0.14106554 | BC7: 0.045788537 | BD7: 0.075756623 | BE7: 0.34060125 | BF7: 10.184238 | BG7: 1.6435113 | BH7: 6.771497 | BI7: 17.313963 | BJ7: 1.3917085 | BK7: 1.7993804 | BL7: 0.044228218 | BM7: 9.6515642 | BN7: 3.2778161 | BO7: 0.66709537 | BP7: 1.6784255 | BQ7: 5.3606016 | BR7: 77.274263 | BS7: 21.397552 | BT7: 29.359845 | BU7: 132.00166 | BV7: 3.8738846 | BW7: 0.51419518 | BX7: 2.7485594 | BY7: 5.4282552 | BZ7: 5.0406649 | CA7: 0.64399141 | CB7: 3.0668142 | CC7: 6.262986 | CD7: 8.9145495 | CE7: 0.67156354 | CF7: 6.316528 | CG7: 9.54352 | CH7: 2.5701759 | CI7: 0.41123563 | CJ7: 1.7826016 | CK7: 4.0273229 | CL7: 8.9145495 | CM7: 0.67156354 | CN7: 6.316528 | CO7: 9.54352 | CP7: 1.5023659 | CQ7: 0.2548189 | CR7: 0.97593476 | CS7: 2.2178738 | CT7: 1.840391 | CU7: 0.28098437 | CV7: 1.1950577 | CW7: 2.5550765 | CX7: -0.2028904 | CY7: 0.34313667 | CZ7: -1.6598535 | DA7: 0.47905576 | DB7: 2.6348082 | DC7: 0.59862531 | DD7: 1.7607796 | DE7: 6.64555 | DF7: 0.13281403 | DG7: 0.042163542 | DH7: 0.071998518 | DI7: 0.294837 | DJ7: 9.8931739 | DK7: 1.3814805 | DL7: 6.771497 | DM7: 16.441322 | DN7: 6.1636168 | DO7: 2.9024897 | DP7: 0.61919505 | DQ7: 15.39142 | DR7: 3.273135 | DS7: 0.66448136 | DT7: 1.6783885 | DU7: 5.2605722 | DV7: 81.785649 | DW7: 22.117454 | DX7: 33.917046 | DY7: 138.89175 | DZ7: 2.9776515 | EA7: 0.5066252 | EB7: 1.9769686 | EC7: 5.1681429 | ED7: 2.6641631 | EE7: 0.37824037 | EF7: 1.80788 | EG7: 3.7324677 | EH7: 5.6418146 | EI7: 0.77107869 | EJ7: 3.7848486 | EK7: 8.500333 | EL7: 1.9790711 | EM7: 0.27514822 | EN7: 1.3965643 | EO7: 3.1073669 | EP7: 8.6443799 | EQ7: 1.5031692 | ER7: 4.766592 | ES7: 13.234565 | ET7: 0.77868927 | EU7: 0.099671055 | EV7: 0.550074 | EW7: 1.1593551 | EX7: 1.0040965 | EY7: 0.13312041 | EZ7: 0.67827226 | FA7: 1.4804417 | FB7: 0.19271982 | FC7: 0.22055639 | FD7: -0.38165186 | FE7: 1.0443701 | FF7: 3.6639679 | FG7: 0.58566426 | FH7: 2.7216154 | FI7: 6.2804992 | FJ7: 4.5459677 | FK7: 1.0142431 | FL7: 2.4969971 | FM7: 7.1554956 | FN7: 4.0984122 | FO7: 0.88847688 | FP7: 2.2419241 | FQ7: 7.2646499 | FR7: 8.1222349 | FS7: 1.4011909 | FT7: 4.528735 | FU7: 12.104804 | FV7: 6.1816066 | FW7: 1.7311101 | FX7: 2.661982 | FY7: 11.720638 | FZ7: 0.062421448 | GA7: 0.009418745 | GB7: 0.04439371 | GC7: 0.094808421 | GD7: 9.7398572 | GE7: 1.5014042 | GF7: 6.6567734 | GG7: 15.585828 | GH7: 0.72943682 | GI7: 0.73468551 | GJ7: 0.049248953 | GK7: 4.1369121 | GL7: 1.4825757 | GM7: 0.18607538 | GN7: 1.0329276 | GO7: 2.2898947 | GP7: 7.9947061 | GQ7: 1.5814089 | GR7: 4.0137897 | GS7: 12.647905 | GT7: 163.64931 | GU7: 23.248858 | GV7: 105.47586 | GW7: 225.25714 | GX7: 2.760707 | GY7: 0.39422567 | GZ7: 1.8787367 | HA7: 4.4959278 | HB7: 2.5956453 | HC7: 0.33869376 | HD7: 1.80788 | HE7: 3.5826029 | HF7: 5.3563523 | HG7: 0.62755726 | HH7: 3.7848486 | HI7: 7.5706866 | HJ7: 1.9027481 | HK7: 0.23265001 | HL7: 1.3965643 | HM7: 2.9133071 | HN7: 7.9384862 | HO7: 1.1166693 | HP7: 4.766592 | HQ7: 11.519834 | HR7: 0.76924817 | HS7: 0.094690764 | HT7: 0.550074 | HU7: 1.101884 | HV7: 0.9856173 | HW7: 0.12352299 | HX7: 0.67827226 | HY7: 1.4359016 | HZ7: 0.15458328 | IA7: 0.19654826 | IB7: -0.39189545 | IC7: 0.97526162 | ID7: 3.4506086 | IE7: 0.43367494 | IF7: 2.6423141 | IG7: 4.936372 | IH7: 4.0419078 | II7: 0.79308072 | IJ7: 2.2890082 | IK7: 6.8912617 | IL7: 3.8965784 | IM7: 0.72651615 | IN7: 2.2419241 | IO7: 6.1338406 | IP7: 7.4660213 | IQ7: 0.97034297 | IR7: 4.528735 | IS7: 9.549516 | IT7: 5.837225 | IU7: 1.3993543 | IV7: 2.64444 | IW7: 9.042777 | IX7: 0.060224931 | IY7: 0.0086115089 | IZ7: 0.04439371 | JA7: 0.090265573 | JB7: 9.497465 | JC7: 1.2839187 | JD7: 6.6567734 | JE7: 14.438144 | JF7: 1.139591 | JG7: 0.95920231 | JH7: 0.049248953 | JI7: 5.438274 | JJ7: 1.4784986 | JK7: 0.1837515 | JL7: 1.0329276 | JM7: 2.2532782 | JN7: 8.6517217 | JO7: 1.5225468 | JP7: 4.9741443 | JQ7: 12.681606 | JR7: 169.20724 | JS7: 22.48795 | JT7: 110.78421 | JU7: 225.25714 | JV7: 2.3190216 | JW7: 0.53099558 | JX7: 0.97868451 | JY7: 4.7581072 | JZ7: 2.8311427 | KA7: 0.79433864 | KB7: 1.2487415 | KC7: 5.184943 | KD7: 5.1501643 | KE7: 1.1126867 | KF7: 2.358282 | KG7: 9.140764 | KH7: 3.8738497 | KI7: 1.3268736 | KJ7: 1.466337 | KK7: 9.140764 | KL7: 5.1501643 | KM7: 1.1126867 | KN7: 2.358282 | KO7: 9.140764 | KP7: 1.0609932 | KQ7: 0.25794569 | KR7: 0.49467898 | KS7: 1.9087593 | KT7: 1.2928094 | KU7: 0.29638246 | KV7: 0.66269254 | KW7: 2.3239941 | KX7: -0.2670436 | KY7: 0.43161803 | KZ7: -1.7524094 | LA7: 0.81440073 | LB7: 2.5692577 | LC7: 0.70053861 | LD7: 1.5639781 | LE7: 5.9889964 | LF7: 1.9733003 | LG7: 0.74803082 | LH7: 0.73554 | LI7: 4.8369 | LJ7: 0.264118 | LK7: 0.053025303 | LL7: 0.12643532 | LM7: 0.42754607 | LN7: 19.280339 | LO7: 9.1553667 | LP7: 3.0075188 | LQ7: 61.256081 | LR7: 2.3105741 | LS7: 0.66395821 | LT7: 0.87516483 | LU7: 4.7386939 | LV7: 17.169686 | LW7: 5.7145139 | LX7: 3.7372844 | LY7: 32.905794 | LZ7: 5.694191 | MA7: 1.892013 | MB7: 2.0674399 | MC7: 13.595454 | MD7: 2.3018034 | ME7: 0.51920146 | MF7: 0.9799667 | MG7: 4.456786 | MH7: 2.7736702 | MI7: 0.71812641 | MJ7: 1.2468121 | MK7: 5.0628063 | ML7: 5.0754735 | MM7: 1.0236797 | MN7: 2.358282 | MO7: 7.89444 | MP7: 3.823376 | MQ7: 1.2506775 | MR7: 1.466337 | MS7: 7.89444 | MT7: 5.0754735 | MU7: 1.0236797 | MV7: 2.358282 | MW7: 7.89444 | MX7: 1.0527348 | MY7: 0.25065851 | MZ7: 0.49483757 | NA7: 1.7672503 | NB7: 1.2802768 | NC7: 0.28377686 | ND7: 0.66269254 | NE7: 2.1458933 | NF7: -0.2541406 | NG7: 0.42391606 | NH7: -1.6909592 | NI7: 0.8182898 | NJ7: 2.5417217 | NK7: 0.67993612 | NL7: 1.5631768 | NM7: 5.7368996 | NN7: 1.9832566 | NO7: 0.74961442 | NP7: 0.7383 | NQ7: 4.86726 | NR7: 0.26105824 | NS7: 0.05035124 | NT7: 0.12660599 | NU7: 0.40088969 | NV7: 19.490604 | NW7: 9.0346064 | NX7: 3.1402035 | NY7: 61.189739 | NZ7: 2.30008 | OA7: 0.65630826 | OB7: 0.87516483 | OC7: 4.5284087 | OD7: 17.389356 | OE7: 5.6489964 | OF7: 3.7151703 | OG7: 32.717877 | OH7: 5.66699 | OI7: 1.8928742 | OJ7: 2.054544 | OK7: 13.54463 | OL7: 1.7595501 | OM7: -0.32970862 | ON7: 3.0418536 | OO7: 7.333088 | OP7: 7.687374 | OQ7: 15.020462 | OR7: 1.4048032 | OS7: 6.4266931e-05 | OT7: 0.0022608042 | OU7: 6.4266931e-05 | OV7: 0.0016139725 | OW7: 0.0020349795 | OX7: 0.00022582466 | OY7: 4.4925921 | OZ7: 1.2189127 | PA7: 2.0194294 | PB7: 8.3219498 | PC7: 88.343761 | PD7: 1.7320199 | PE7: -0.30832922 | PF7: 2.8193679 | PG7: 5.567982 | PH7: 6.319185 | PI7: 11.887167 | PJ7: 1.392537 | PK7: 5.979666e-05 | PL7: 0.0022482629 | PM7: 5.979666e-05 | PN7: 0.0016116864 | PO7: 0.0020282926 | PP7: 0.00021997025 | PQ7: 4.4863272 | PR7: 1.1129465 | PS7: 1.9219044 | PT7: 8.2492805 | PU7: 88.3422 | PV7: 5.1450708 | PW7: 1.0485402 | PX7: 2.1797779 | PY7: 8.519184 | PZ7: 88.831541 | QA7: 5.1407894 | QB7: 0.94238395 | QC7: 2.0665762 | QD7: 8.4410143 | QE7: 88.833038 | QF7: 5.6970984e-05 | QG7: 0.0018458601 | QH7: 0.0023533279 | QI7: 0.00024605748 | QJ7: 5.2592375e-05 | QK7: 0.0018435563 | QL7: 0.0023464797 | QM7: 0.00023953404 | QN7: 14.57925 | QO7: 0.029238803 | QP7: 5.4581289 | QQ7: 173.76399 | QR7: 14.494923 | QS7: 0.025434948 | QT7: 5.4577483 | QU7: 173.76272
